Workbook

Sheet 1
A1: Лист для ежедневной регистрации грязного белья и постельных принадлежностей (в кг)
A2: Дата | B2: Вид стирки | C2: Количество | D2: Общее время | E2: EMULSIFIER | F2: ALKALINE | G2: BLEACH | H2: SOFTENER | I2: NEUTRLIZER | J2: Вес | AH2: Всего Вес | AI2: Ваниш | AK2: Ленор | AM2: Порошок
J3: 1 | L3: 2 | N3: 3 | P3: 4 | R3: 5 | T3: 6 | V3: 7 | X3: 8 | Z3: 9 | AB3: 10 | AD3: 11 | AF3: 12
J4: день | K4: ночь | L4: день | M4: ночь | N4: день | O4: ночь | P4: день | Q4: ночь | R4: день | S4: ночь | T4: день | U4: ночь | V4: день | W4: ночь | X4: день | Y4: ночь | Z4: день | AA4: ночь | AB4: день | AC4: ночь | AD4: день | AE4: ночь | AF4: день | AG4: ночь | AI4: Кол-во | AJ4: Общее | AK4: Кол-во | AL4: Общее | AM4: Кол-во | AN4: Общее
B5: Постель белая | C5: =COUNT(J5:AG9) | D5: =C5*57 | E5: =C5*55*3 | F5: =C5*55*8 | G5: =C5*55*6 | H5: =C5*55*4 | I5: =C5*55*1 | AH5: =SUM(J5:AG9) | AJ5: =AI5*5 | AL5: =AK5*50 | AN5: =AM5*175
B10: Махра белая | C10: =COUNT(J10:AG14) | D10: =C10*51 | E10: =C10*55*3 | F10: =C10*55*8 | G10: =C10*55*6 | H10: =C10*55*5 | I10: =C10*55*1 | AH10: =SUM(J10:AG14) | AJ10: =AI10*5 | AL10: =AK10*50 | AN10: =AM10*175
B15: Униформа белая | C15: =COUNT(J15:AG19) | D15: =C15*55 | E15: =C15*55*3 | F15: =C15*55*8 | G15: =C15*55*5 | H15: =C15*55*3 | I15: =C15*55*1 | AH15: =SUM(J15:AG19) | AJ15: =AI15*5 | AL15: =AK15*50 | AN15: =AM15*175
B20: Униформа темная | C20: =COUNT(J20:AG24) | D20: =C20*45 | E20: =C20*55*2 | F20: =C20*55*6 | G20: =C20*55*0 | H20: =C20*55*3 | I20: =C20*55*1 | AH20: =SUM(J20:AG24) | AJ20: =AI20*5 | AL20: =AK20*50 | AN20: =AM20*175
B25: Синтетика | C25: =COUNT(J25:AG29) | D25: =C25*38 | E25: =C25*55*3 | F25: =C25*55*5 | G25: =C25*55*0 | H25: =C25*55*3 | I25: =C25*55*1 | AH25: =SUM(J25:AG29) | AJ25: =AI25*5 | AL25: =AK25*50 | AN25: =AM25*175
B30: Деликатная | C30: =COUNT(J30:AG34) | D30: =C30*50 | E30: =C30*55*2 | F30: =C30*55*4 | G30: =C30*55*0 | H30: =C30*55*3 | I30: =C30*55*1 | AH30: =SUM(J30:AG34) | AJ30: =AI30*5 | AL30: =AK30*50 | AN30: =AM30*175
B35: Спецодежда | C35: =COUNT(J35:AG39) | D35: =C35*42 | E35: =C35*55*3 | F35: =C35*55*10 | G35: =C35*55*0 | H35: =C35*55*3 | I35: =C35*55*1 | AH35: =SUM(J35:AG39) | AJ35: =AI35*5 | AL35: =AK35*50 | AN35: =AM35*175
A40: ИТОГО | C40: =C5+C10+C15+C20+C25+C30+C35 | D40: =D5+D10+D15+D20+D25+D30+D35 | E40: =E5+E10+E15+E20+E25+E30+E35 | F40: =F5+F10+F15+F20+F25+F30+F35 | G40: =G5+G10+G15+G20+G25+G30+G35 | H40: =H5+H10+H15+H20+H25+H30+H35 | I40: =I5+I10+I15+I20+I25+I30+I35 | J40: =J5+J6+J7+J8+J9+J10+J11+J12+J13+J14+J15+J16+J17+J18+J19+J20+J21+J22+J23+J24+J25+J26+J27+J28+J29+J30+J31+J32+J33+J34+J35+J36+J37+J38+J39 | K40: =K5+K6+K7+K8+K9+K10+K11+K12+K13+K14+K15+K16+K17+K18+K19+K20+K21+K22+K23+K24+K25+K26+K27+K28+K29+K30+K31+K32+K33+K34+K35+K36+K37+K38+K39 | L40: =L5+L6+L7+L8+L9+L10+L11+L12+L13+L14+L15+L16+L17+L18+L19+L20+L21+L22+L23+L24+L25+L26+L27+L28+L29+L30+L31+L32+L33+L34+L35+L36+L37+L38+L39 | M40: =M5+M6+M7+M8+M9+M10+M11+M12+M13+M14+M15+M16+M17+M18+M19+M20+M21+M22+M23+M24+M25+M26+M27+M28+M29+M30+M31+M32+M33+M34+M35+M36+M37+M38+M39 | N40: =N5+N6+N7+N8+N9+N10+N11+N12+N13+N14+N15+N16+N17+N18+N19+N20+N21+N22+N23+N24+N25+N26+N27+N28+N29+N30+N31+N32+N33+N34+N35+N36+N37+N38+N39 | O40: =O5+O6+O7+O8+O9+O10+O11+O12+O13+O14+O15+O16+O17+O18+O19+O20+O21+O22+O23+O24+O25+O26+O27+O28+O29+O30+O31+O32+O33+O34+O35+O36+O37+O38+O39 | P40: =P5+P6+P7+P8+P9+P10+P11+P12+P13+P14+P15+P16+P17+P18+P19+P20+P21+P22+P23+P24+P25+P26+P27+P28+P29+P30+P31+P32+P33+P34+P35+P36+P37+P38+P39 | Q40: =Q5+Q6+Q7+Q8+Q9+Q10+Q11+Q12+Q13+Q14+Q15+Q16+Q17+Q18+Q19+Q20+Q21+Q22+Q23+Q24+Q25+Q26+Q27+Q28+Q29+Q30+Q31+Q32+Q33+Q34+Q35+Q36+Q37+Q38+Q39 | ... AG40: =AG5+AG6+AG7+AG8+AG9+AG10+AG11+AG12+AG13+AG14+AG15+AG16+AG17+AG18+AG19+AG20+AG21+AG22+AG23+AG24+AG25+AG26+AG27+AG28+AG29+AG30+AG31+AG32+AG33+AG34+AG35+AG36+AG37+AG38+AG39 | AH40: =AH5+AH10+AH15+AH20+AH25+AH30+AH35 | AI40: =AI5+AI10+AI15+AI20+AI25+AI30+AI35 | AJ40: =AJ5+AJ10+AJ15+AJ20+AJ25+AJ30+AJ35 | AK40: =AK5+AK10+AK15+AK20+AK25+AK30+AK35 | AL40: =AL5+AL10+AL15+AL20+AL25+AL30+AL35 | AM40: =AM5+AM10+AM15+AM20+AM25+AM30+AM35 | AN40: =AN5+AN10+AN15+AN20+AN25+AN30+AN35

Sheet 2
A1: Лист для ежедневной регистрации грязного белья и постельных принадлежностей (в кг)
A2: Дата | B2: Вид стирки | C2: Количество | D2: Общее время | E2: EMULSIFIER | F2: ALKALINE | G2: BLEACH | H2: SOFTENER | I2: NEUTRLIZER | J2: Вес | AH2: Всего Вес | AI2: Ваниш | AK2: Ленор | AM2: Порошок
J3: 1 | L3: 2 | N3: 3 | P3: 4 | R3: 5 | T3: 6 | V3: 7 | X3: 8 | Z3: 9 | AB3: 10 | AD3: 11 | AF3: 12
J4: день | K4: ночь | L4: день | M4: ночь | N4: день | O4: ночь | P4: день | Q4: ночь | R4: день | S4: ночь | T4: день | U4: ночь | V4: день | W4: ночь | X4: день | Y4: ночь | Z4: день | AA4: ночь | AB4: день | AC4: ночь | AD4: день | AE4: ночь | AF4: день | AG4: ночь | AI4: Кол-во | AJ4: Общее | AK4: Кол-во | AL4: Общее | AM4: Кол-во | AN4: Общее
B5: Постель белая | C5: =COUNT(J5:AG9) | D5: =C5*57 | E5: =C5*55*3 | F5: =C5*55*8 | G5: =C5*55*6 | H5: =C5*55*4 | I5: =C5*55*1 | AH5: =SUM(J5:AG9) | AJ5: =AI5*5 | AL5: =AK5*50 | AN5: =AM5*175
B10: Махра белая | C10: =COUNT(J10:AG14) | D10: =C10*51 | E10: =C10*55*3 | F10: =C10*55*8 | G10: =C10*55*6 | H10: =C10*55*5 | I10: =C10*55*1 | AH10: =SUM(J10:AG14) | AJ10: =AI10*5 | AL10: =AK10*50 | AN10: =AM10*175
B15: Униформа белая | C15: =COUNT(J15:AG19) | D15: =C15*55 | E15: =C15*55*3 | F15: =C15*55*8 | G15: =C15*55*5 | H15: =C15*55*3 | I15: =C15*55*1 | AH15: =SUM(J15:AG19) | AJ15: =AI15*5 | AL15: =AK15*50 | AN15: =AM15*175
B20: Униформа темная | C20: =COUNT(J20:AG24) | D20: =C20*45 | E20: =C20*55*2 | F20: =C20*55*6 | G20: =C20*55*0 | H20: =C20*55*3 | I20: =C20*55*1 | AH20: =SUM(J20:AG24) | AJ20: =AI20*5 | AL20: =AK20*50 | AN20: =AM20*175
B25: Синтетика | C25: =COUNT(J25:AG29) | D25: =C25*38 | E25: =C25*55*3 | F25: =C25*55*5 | G25: =C25*55*0 | H25: =C25*55*3 | I25: =C25*55*1 | AH25: =SUM(J25:AG29) | AJ25: =AI25*5 | AL25: =AK25*50 | AN25: =AM25*175
B30: Деликатная | C30: =COUNT(J30:AG34) | D30: =C30*50 | E30: =C30*55*2 | F30: =C30*55*4 | G30: =C30*55*0 | H30: =C30*55*3 | I30: =C30*55*1 | AH30: =SUM(J30:AG34) | AJ30: =AI30*5 | AL30: =AK30*50 | AN30: =AM30*175
B35: Спецодежда | C35: =COUNT(J35:AG39) | D35: =C35*42 | E35: =C35*55*3 | F35: =C35*55*10 | G35: =C35*55*0 | H35: =C35*55*3 | I35: =C35*55*1 | AH35: =SUM(J35:AG39) | AJ35: =AI35*5 | AL35: =AK35*50 | AN35: =AM35*175
A40: ИТОГО | C40: =C5+C10+C15+C20+C25+C30+C35 | D40: =D5+D10+D15+D20+D25+D30+D35 | E40: =E5+E10+E15+E20+E25+E30+E35 | F40: =F5+F10+F15+F20+F25+F30+F35 | G40: =G5+G10+G15+G20+G25+G30+G35 | H40: =H5+H10+H15+H20+H25+H30+H35 | I40: =I5+I10+I15+I20+I25+I30+I35 | J40: =J5+J6+J7+J8+J9+J10+J11+J12+J13+J14+J15+J16+J17+J18+J19+J20+J21+J22+J23+J24+J25+J26+J27+J28+J29+J30+J31+J32+J33+J34+J35+J36+J37+J38+J39 | K40: =K5+K6+K7+K8+K9+K10+K11+K12+K13+K14+K15+K16+K17+K18+K19+K20+K21+K22+K23+K24+K25+K26+K27+K28+K29+K30+K31+K32+K33+K34+K35+K36+K37+K38+K39 | L40: =L5+L6+L7+L8+L9+L10+L11+L12+L13+L14+L15+L16+L17+L18+L19+L20+L21+L22+L23+L24+L25+L26+L27+L28+L29+L30+L31+L32+L33+L34+L35+L36+L37+L38+L39 | M40: =M5+M6+M7+M8+M9+M10+M11+M12+M13+M14+M15+M16+M17+M18+M19+M20+M21+M22+M23+M24+M25+M26+M27+M28+M29+M30+M31+M32+M33+M34+M35+M36+M37+M38+M39 | N40: =N5+N6+N7+N8+N9+N10+N11+N12+N13+N14+N15+N16+N17+N18+N19+N20+N21+N22+N23+N24+N25+N26+N27+N28+N29+N30+N31+N32+N33+N34+N35+N36+N37+N38+N39 | O40: =O5+O6+O7+O8+O9+O10+O11+O12+O13+O14+O15+O16+O17+O18+O19+O20+O21+O22+O23+O24+O25+O26+O27+O28+O29+O30+O31+O32+O33+O34+O35+O36+O37+O38+O39 | P40: =P5+P6+P7+P8+P9+P10+P11+P12+P13+P14+P15+P16+P17+P18+P19+P20+P21+P22+P23+P24+P25+P26+P27+P28+P29+P30+P31+P32+P33+P34+P35+P36+P37+P38+P39 | Q40: =Q5+Q6+Q7+Q8+Q9+Q10+Q11+Q12+Q13+Q14+Q15+Q16+Q17+Q18+Q19+Q20+Q21+Q22+Q23+Q24+Q25+Q26+Q27+Q28+Q29+Q30+Q31+Q32+Q33+Q34+Q35+Q36+Q37+Q38+Q39 | ... AG40: =AG5+AG6+AG7+AG8+AG9+AG10+AG11+AG12+AG13+AG14+AG15+AG16+AG17+AG18+AG19+AG20+AG21+AG22+AG23+AG24+AG25+AG26+AG27+AG28+AG29+AG30+AG31+AG32+AG33+AG34+AG35+AG36+AG37+AG38+AG39 | AH40: =AH5+AH10+AH15+AH20+AH25+AH30+AH35 | AI40: =AI5+AI10+AI15+AI20+AI25+AI30+AI35 | AJ40: =AJ5+AJ10+AJ15+AJ20+AJ25+AJ30+AJ35 | AK40: =AK5+AK10+AK15+AK20+AK25+AK30+AK35 | AL40: =AL5+AL10+AL15+AL20+AL25+AL30+AL35 | AM40: =AM5+AM10+AM15+AM20+AM25+AM30+AM35 | AN40: =AN5+AN10+AN15+AN20+AN25+AN30+AN35

Sheet 3
A1: Лист для ежедневной регистрации грязного белья и постельных принадлежностей (в кг)
A2: Дата | B2: Вид стирки | C2: Количество | D2: Общее время | E2: EMULSIFIER | F2: ALKALINE | G2: BLEACH | H2: SOFTENER | I2: NEUTRLIZER | J2: Вес | AH2: Всего Вес | AI2: Ваниш | AK2: Ленор | AM2: Порошок
J3: 1 | L3: 2 | N3: 3 | P3: 4 | R3: 5 | T3: 6 | V3: 7 | X3: 8 | Z3: 9 | AB3: 10 | AD3: 11 | AF3: 12
J4: день | K4: ночь | L4: день | M4: ночь | N4: день | O4: ночь | P4: день | Q4: ночь | R4: день | S4: ночь | T4: день | U4: ночь | V4: день | W4: ночь | X4: день | Y4: ночь | Z4: день | AA4: ночь | AB4: день | AC4: ночь | AD4: день | AE4: ночь | AF4: день | AG4: ночь | AI4: Кол-во | AJ4: Общее | AK4: Кол-во | AL4: Общее | AM4: Кол-во | AN4: Общее
B5: Постель белая | C5: =COUNT(J5:AG9) | D5: =C5*57 | E5: =C5*55*3 | F5: =C5*55*8 | G5: =C5*55*6 | H5: =C5*55*4 | I5: =C5*55*1 | AH5: =SUM(J5:AG9) | AJ5: =AI5*5 | AL5: =AK5*50 | AN5: =AM5*175
B10: Махра белая | C10: =COUNT(J10:AG14) | D10: =C10*51 | E10: =C10*55*3 | F10: =C10*55*8 | G10: =C10*55*6 | H10: =C10*55*5 | I10: =C10*55*1 | AH10: =SUM(J10:AG14) | AJ10: =AI10*5 | AL10: =AK10*50 | AN10: =AM10*175
B15: Униформа белая | C15: =COUNT(J15:AG19) | D15: =C15*55 | E15: =C15*55*3 | F15: =C15*55*8 | G15: =C15*55*5 | H15: =C15*55*3 | I15: =C15*55*1 | AH15: =SUM(J15:AG19) | AJ15: =AI15*5 | AL15: =AK15*50 | AN15: =AM15*175
B20: Униформа темная | C20: =COUNT(J20:AG24) | D20: =C20*45 | E20: =C20*55*2 | F20: =C20*55*6 | G20: =C20*55*0 | H20: =C20*55*3 | I20: =C20*55*1 | AH20: =SUM(J20:AG24) | AJ20: =AI20*5 | AL20: =AK20*50 | AN20: =AM20*175
B25: Синтетика | C25: =COUNT(J25:AG29) | D25: =C25*38 | E25: =C25*55*3 | F25: =C25*55*5 | G25: =C25*55*0 | H25: =C25*55*3 | I25: =C25*55*1 | AH25: =SUM(J25:AG29) | AJ25: =AI25*5 | AL25: =AK25*50 | AN25: =AM25*175
B30: Деликатная | C30: =COUNT(J30:AG34) | D30: =C30*50 | E30: =C30*55*2 | F30: =C30*55*4 | G30: =C30*55*0 | H30: =C30*55*3 | I30: =C30*55*1 | AH30: =SUM(J30:AG34) | AJ30: =AI30*5 | AL30: =AK30*50 | AN30: =AM30*175
B35: Спецодежда | C35: =COUNT(J35:AG39) | D35: =C35*42 | E35: =C35*55*3 | F35: =C35*55*10 | G35: =C35*55*0 | H35: =C35*55*3 | I35: =C35*55*1 | AH35: =SUM(J35:AG39) | AJ35: =AI35*5 | AL35: =AK35*50 | AN35: =AM35*175
A40: ИТОГО | C40: =C5+C10+C15+C20+C25+C30+C35 | D40: =D5+D10+D15+D20+D25+D30+D35 | E40: =E5+E10+E15+E20+E25+E30+E35 | F40: =F5+F10+F15+F20+F25+F30+F35 | G40: =G5+G10+G15+G20+G25+G30+G35 | H40: =H5+H10+H15+H20+H25+H30+H35 | I40: =I5+I10+I15+I20+I25+I30+I35 | J40: =J5+J6+J7+J8+J9+J10+J11+J12+J13+J14+J15+J16+J17+J18+J19+J20+J21+J22+J23+J24+J25+J26+J27+J28+J29+J30+J31+J32+J33+J34+J35+J36+J37+J38+J39 | K40: =K5+K6+K7+K8+K9+K10+K11+K12+K13+K14+K15+K16+K17+K18+K19+K20+K21+K22+K23+K24+K25+K26+K27+K28+K29+K30+K31+K32+K33+K34+K35+K36+K37+K38+K39 | L40: =L5+L6+L7+L8+L9+L10+L11+L12+L13+L14+L15+L16+L17+L18+L19+L20+L21+L22+L23+L24+L25+L26+L27+L28+L29+L30+L31+L32+L33+L34+L35+L36+L37+L38+L39 | M40: =M5+M6+M7+M8+M9+M10+M11+M12+M13+M14+M15+M16+M17+M18+M19+M20+M21+M22+M23+M24+M25+M26+M27+M28+M29+M30+M31+M32+M33+M34+M35+M36+M37+M38+M39 | N40: =N5+N6+N7+N8+N9+N10+N11+N12+N13+N14+N15+N16+N17+N18+N19+N20+N21+N22+N23+N24+N25+N26+N27+N28+N29+N30+N31+N32+N33+N34+N35+N36+N37+N38+N39 | O40: =O5+O6+O7+O8+O9+O10+O11+O12+O13+O14+O15+O16+O17+O18+O19+O20+O21+O22+O23+O24+O25+O26+O27+O28+O29+O30+O31+O32+O33+O34+O35+O36+O37+O38+O39 | P40: =P5+P6+P7+P8+P9+P10+P11+P12+P13+P14+P15+P16+P17+P18+P19+P20+P21+P22+P23+P24+P25+P26+P27+P28+P29+P30+P31+P32+P33+P34+P35+P36+P37+P38+P39 | Q40: =Q5+Q6+Q7+Q8+Q9+Q10+Q11+Q12+Q13+Q14+Q15+Q16+Q17+Q18+Q19+Q20+Q21+Q22+Q23+Q24+Q25+Q26+Q27+Q28+Q29+Q30+Q31+Q32+Q33+Q34+Q35+Q36+Q37+Q38+Q39 | ... AG40: =AG5+AG6+AG7+AG8+AG9+AG10+AG11+AG12+AG13+AG14+AG15+AG16+AG17+AG18+AG19+AG20+AG21+AG22+AG23+AG24+AG25+AG26+AG27+AG28+AG29+AG30+AG31+AG32+AG33+AG34+AG35+AG36+AG37+AG38+AG39 | AH40: =AH5+AH10+AH15+AH20+AH25+AH30+AH35 | AI40: =AI5+AI10+AI15+AI20+AI25+AI30+AI35 | AJ40: =AJ5+AJ10+AJ15+AJ20+AJ25+AJ30+AJ35 | AK40: =AK5+AK10+AK15+AK20+AK25+AK30+AK35 | AL40: =AL5+AL10+AL15+AL20+AL25+AL30+AL35 | AM40: =AM5+AM10+AM15+AM20+AM25+AM30+AM35 | AN40: =AN5+AN10+AN15+AN20+AN25+AN30+AN35

Sheet 4
A1: Лист для ежедневной регистрации грязного белья и постельных принадлежностей (в кг)
A2: Дата | B2: Вид стирки | C2: Количество | D2: Общее время | E2: EMULSIFIER | F2: ALKALINE | G2: BLEACH | H2: SOFTENER | I2: NEUTRLIZER | J2: Вес | AH2: Всего Вес | AI2: Ваниш | AK2: Ленор | AM2: Порошок
J3: 1 | L3: 2 | N3: 3 | P3: 4 | R3: 5 | T3: 6 | V3: 7 | X3: 8 | Z3: 9 | AB3: 10 | AD3: 11 | AF3: 12
J4: день | K4: ночь | L4: день | M4: ночь | N4: день | O4: ночь | P4: день | Q4: ночь | R4: день | S4: ночь | T4: день | U4: ночь | V4: день | W4: ночь | X4: день | Y4: ночь | Z4: день | AA4: ночь | AB4: день | AC4: ночь | AD4: день | AE4: ночь | AF4: день | AG4: ночь | AI4: Кол-во | AJ4: Общее | AK4: Кол-во | AL4: Общее | AM4: Кол-во | AN4: Общее
B5: Постель белая | C5: =COUNT(J5:AG9) | D5: =C5*57 | E5: =C5*55*3 | F5: =C5*55*8 | G5: =C5*55*6 | H5: =C5*55*4 | I5: =C5*55*1 | AH5: =SUM(J5:AG9) | AJ5: =AI5*5 | AL5: =AK5*50 | AN5: =AM5*175
B10: Махра белая | C10: =COUNT(J10:AG14) | D10: =C10*51 | E10: =C10*55*3 | F10: =C10*55*8 | G10: =C10*55*6 | H10: =C10*55*5 | I10: =C10*55*1 | AH10: =SUM(J10:AG14) | AJ10: =AI10*5 | AL10: =AK10*50 | AN10: =AM10*175
B15: Униформа белая | C15: =COUNT(J15:AG19) | D15: =C15*55 | E15: =C15*55*3 | F15: =C15*55*8 | G15: =C15*55*5 | H15: =C15*55*3 | I15: =C15*55*1 | AH15: =SUM(J15:AG19) | AJ15: =AI15*5 | AL15: =AK15*50 | AN15: =AM15*175
B20: Униформа темная | C20: =COUNT(J20:AG24) | D20: =C20*45 | E20: =C20*55*2 | F20: =C20*55*6 | G20: =C20*55*0 | H20: =C20*55*3 | I20: =C20*55*1 | AH20: =SUM(J20:AG24) | AJ20: =AI20*5 | AL20: =AK20*50 | AN20: =AM20*175
B25: Синтетика | C25: =COUNT(J25:AG29) | D25: =C25*38 | E25: =C25*55*3 | F25: =C25*55*5 | G25: =C25*55*0 | H25: =C25*55*3 | I25: =C25*55*1 | AH25: =SUM(J25:AG29) | AJ25: =AI25*5 | AL25: =AK25*50 | AN25: =AM25*175
B30: Деликатная | C30: =COUNT(J30:AG34) | D30: =C30*50 | E30: =C30*55*2 | F30: =C30*55*4 | G30: =C30*55*0 | H30: =C30*55*3 | I30: =C30*55*1 | AH30: =SUM(J30:AG34) | AJ30: =AI30*5 | AL30: =AK30*50 | AN30: =AM30*175
B35: Спецодежда | C35: =COUNT(J35:AG39) | D35: =C35*42 | E35: =C35*55*3 | F35: =C35*55*10 | G35: =C35*55*0 | H35: =C35*55*3 | I35: =C35*55*1 | AH35: =SUM(J35:AG39) | AJ35: =AI35*5 | AL35: =AK35*50 | AN35: =AM35*175
A40: ИТОГО | C40: =C5+C10+C15+C20+C25+C30+C35 | D40: =D5+D10+D15+D20+D25+D30+D35 | E40: =E5+E10+E15+E20+E25+E30+E35 | F40: =F5+F10+F15+F20+F25+F30+F35 | G40: =G5+G10+G15+G20+G25+G30+G35 | H40: =H5+H10+H15+H20+H25+H30+H35 | I40: =I5+I10+I15+I20+I25+I30+I35 | J40: =J5+J6+J7+J8+J9+J10+J11+J12+J13+J14+J15+J16+J17+J18+J19+J20+J21+J22+J23+J24+J25+J26+J27+J28+J29+J30+J31+J32+J33+J34+J35+J36+J37+J38+J39 | K40: =K5+K6+K7+K8+K9+K10+K11+K12+K13+K14+K15+K16+K17+K18+K19+K20+K21+K22+K23+K24+K25+K26+K27+K28+K29+K30+K31+K32+K33+K34+K35+K36+K37+K38+K39 | L40: =L5+L6+L7+L8+L9+L10+L11+L12+L13+L14+L15+L16+L17+L18+L19+L20+L21+L22+L23+L24+L25+L26+L27+L28+L29+L30+L31+L32+L33+L34+L35+L36+L37+L38+L39 | M40: =M5+M6+M7+M8+M9+M10+M11+M12+M13+M14+M15+M16+M17+M18+M19+M20+M21+M22+M23+M24+M25+M26+M27+M28+M29+M30+M31+M32+M33+M34+M35+M36+M37+M38+M39 | N40: =N5+N6+N7+N8+N9+N10+N11+N12+N13+N14+N15+N16+N17+N18+N19+N20+N21+N22+N23+N24+N25+N26+N27+N28+N29+N30+N31+N32+N33+N34+N35+N36+N37+N38+N39 | O40: =O5+O6+O7+O8+O9+O10+O11+O12+O13+O14+O15+O16+O17+O18+O19+O20+O21+O22+O23+O24+O25+O26+O27+O28+O29+O30+O31+O32+O33+O34+O35+O36+O37+O38+O39 | P40: =P5+P6+P7+P8+P9+P10+P11+P12+P13+P14+P15+P16+P17+P18+P19+P20+P21+P22+P23+P24+P25+P26+P27+P28+P29+P30+P31+P32+P33+P34+P35+P36+P37+P38+P39 | Q40: =Q5+Q6+Q7+Q8+Q9+Q10+Q11+Q12+Q13+Q14+Q15+Q16+Q17+Q18+Q19+Q20+Q21+Q22+Q23+Q24+Q25+Q26+Q27+Q28+Q29+Q30+Q31+Q32+Q33+Q34+Q35+Q36+Q37+Q38+Q39 | ... AG40: =AG5+AG6+AG7+AG8+AG9+AG10+AG11+AG12+AG13+AG14+AG15+AG16+AG17+AG18+AG19+AG20+AG21+AG22+AG23+AG24+AG25+AG26+AG27+AG28+AG29+AG30+AG31+AG32+AG33+AG34+AG35+AG36+AG37+AG38+AG39 | AH40: =AH5+AH10+AH15+AH20+AH25+AH30+AH35 | AI40: =AI5+AI10+AI15+AI20+AI25+AI30+AI35 | AJ40: =AJ5+AJ10+AJ15+AJ20+AJ25+AJ30+AJ35 | AK40: =AK5+AK10+AK15+AK20+AK25+AK30+AK35 | AL40: =AL5+AL10+AL15+AL20+AL25+AL30+AL35 | AM40: =AM5+AM10+AM15+AM20+AM25+AM30+AM35 | AN40: =AN5+AN10+AN15+AN20+AN25+AN30+AN35

Sheet 5
A1: Лист для ежедневной регистрации грязного белья и постельных принадлежностей (в кг)
A2: Дата | B2: Вид стирки | C2: Количество | D2: Общее время | E2: EMULSIFIER | F2: ALKALINE | G2: BLEACH | H2: SOFTENER | I2: NEUTRLIZER | J2: Вес | AH2: Всего Вес | AI2: Ваниш | AK2: Ленор | AM2: Порошок
J3: 1 | L3: 2 | N3: 3 | P3: 4 | R3: 5 | T3: 6 | V3: 7 | X3: 8 | Z3: 9 | AB3: 10 | AD3: 11 | AF3: 12
J4: день | K4: ночь | L4: день | M4: ночь | N4: день | O4: ночь | P4: день | Q4: ночь | R4: день | S4: ночь | T4: день | U4: ночь | V4: день | W4: ночь | X4: день | Y4: ночь | Z4: день | AA4: ночь | AB4: день | AC4: ночь | AD4: день | AE4: ночь | AF4: день | AG4: ночь | AI4: Кол-во | AJ4: Общее | AK4: Кол-во | AL4: Общее | AM4: Кол-во | AN4: Общее
B5: Постель белая | C5: =COUNT(J5:AG9) | D5: =C5*57 | E5: =C5*55*3 | F5: =C5*55*8 | G5: =C5*55*6 | H5: =C5*55*4 | I5: =C5*55*1 | AH5: =SUM(J5:AG9) | AJ5: =AI5*5 | AL5: =AK5*50 | AN5: =AM5*175
B10: Махра белая | C10: =COUNT(J10:AG14) | D10: =C10*51 | E10: =C10*55*3 | F10: =C10*55*8 | G10: =C10*55*6 | H10: =C10*55*5 | I10: =C10*55*1 | AH10: =SUM(J10:AG14) | AJ10: =AI10*5 | AL10: =AK10*50 | AN10: =AM10*175
B15: Униформа белая | C15: =COUNT(J15:AG19) | D15: =C15*55 | E15: =C15*55*3 | F15: =C15*55*8 | G15: =C15*55*5 | H15: =C15*55*3 | I15: =C15*55*1 | AH15: =SUM(J15:AG19) | AJ15: =AI15*5 | AL15: =AK15*50 | AN15: =AM15*175
B20: Униформа темная | C20: =COUNT(J20:AG24) | D20: =C20*45 | E20: =C20*55*2 | F20: =C20*55*6 | G20: =C20*55*0 | H20: =C20*55*3 | I20: =C20*55*1 | AH20: =SUM(J20:AG24) | AJ20: =AI20*5 | AL20: =AK20*50 | AN20: =AM20*175
B25: Синтетика | C25: =COUNT(J25:AG29) | D25: =C25*38 | E25: =C25*55*3 | F25: =C25*55*5 | G25: =C25*55*0 | H25: =C25*55*3 | I25: =C25*55*1 | AH25: =SUM(J25:AG29) | AJ25: =AI25*5 | AL25: =AK25*50 | AN25: =AM25*175
B30: Деликатная | C30: =COUNT(J30:AG34) | D30: =C30*50 | E30: =C30*55*2 | F30: =C30*55*4 | G30: =C30*55*0 | H30: =C30*55*3 | I30: =C30*55*1 | AH30: =SUM(J30:AG34) | AJ30: =AI30*5 | AL30: =AK30*50 | AN30: =AM30*175
B35: Спецодежда | C35: =COUNT(J35:AG39) | D35: =C35*42 | E35: =C35*55*3 | F35: =C35*55*10 | G35: =C35*55*0 | H35: =C35*55*3 | I35: =C35*55*1 | AH35: =SUM(J35:AG39) | AJ35: =AI35*5 | AL35: =AK35*50 | AN35: =AM35*175
A40: ИТОГО | C40: =C5+C10+C15+C20+C25+C30+C35 | D40: =D5+D10+D15+D20+D25+D30+D35 | E40: =E5+E10+E15+E20+E25+E30+E35 | F40: =F5+F10+F15+F20+F25+F30+F35 | G40: =G5+G10+G15+G20+G25+G30+G35 | H40: =H5+H10+H15+H20+H25+H30+H35 | I40: =I5+I10+I15+I20+I25+I30+I35 | J40: =J5+J6+J7+J8+J9+J10+J11+J12+J13+J14+J15+J16+J17+J18+J19+J20+J21+J22+J23+J24+J25+J26+J27+J28+J29+J30+J31+J32+J33+J34+J35+J36+J37+J38+J39 | K40: =K5+K6+K7+K8+K9+K10+K11+K12+K13+K14+K15+K16+K17+K18+K19+K20+K21+K22+K23+K24+K25+K26+K27+K28+K29+K30+K31+K32+K33+K34+K35+K36+K37+K38+K39 | L40: =L5+L6+L7+L8+L9+L10+L11+L12+L13+L14+L15+L16+L17+L18+L19+L20+L21+L22+L23+L24+L25+L26+L27+L28+L29+L30+L31+L32+L33+L34+L35+L36+L37+L38+L39 | M40: =M5+M6+M7+M8+M9+M10+M11+M12+M13+M14+M15+M16+M17+M18+M19+M20+M21+M22+M23+M24+M25+M26+M27+M28+M29+M30+M31+M32+M33+M34+M35+M36+M37+M38+M39 | N40: =N5+N6+N7+N8+N9+N10+N11+N12+N13+N14+N15+N16+N17+N18+N19+N20+N21+N22+N23+N24+N25+N26+N27+N28+N29+N30+N31+N32+N33+N34+N35+N36+N37+N38+N39 | O40: =O5+O6+O7+O8+O9+O10+O11+O12+O13+O14+O15+O16+O17+O18+O19+O20+O21+O22+O23+O24+O25+O26+O27+O28+O29+O30+O31+O32+O33+O34+O35+O36+O37+O38+O39 | P40: =P5+P6+P7+P8+P9+P10+P11+P12+P13+P14+P15+P16+P17+P18+P19+P20+P21+P22+P23+P24+P25+P26+P27+P28+P29+P30+P31+P32+P33+P34+P35+P36+P37+P38+P39 | Q40: =Q5+Q6+Q7+Q8+Q9+Q10+Q11+Q12+Q13+Q14+Q15+Q16+Q17+Q18+Q19+Q20+Q21+Q22+Q23+Q24+Q25+Q26+Q27+Q28+Q29+Q30+Q31+Q32+Q33+Q34+Q35+Q36+Q37+Q38+Q39 | ... AG40: =AG5+AG6+AG7+AG8+AG9+AG10+AG11+AG12+AG13+AG14+AG15+AG16+AG17+AG18+AG19+AG20+AG21+AG22+AG23+AG24+AG25+AG26+AG27+AG28+AG29+AG30+AG31+AG32+AG33+AG34+AG35+AG36+AG37+AG38+AG39 | AH40: =AH5+AH10+AH15+AH20+AH25+AH30+AH35 | AI40: =AI5+AI10+AI15+AI20+AI25+AI30+AI35 | AJ40: =AJ5+AJ10+AJ15+AJ20+AJ25+AJ30+AJ35 | AK40: =AK5+AK10+AK15+AK20+AK25+AK30+AK35 | AL40: =AL5+AL10+AL15+AL20+AL25+AL30+AL35 | AM40: =AM5+AM10+AM15+AM20+AM25+AM30+AM35 | AN40: =AN5+AN10+AN15+AN20+AN25+AN30+AN35

Sheet 6
A1: Лист для ежедневной регистрации грязного белья и постельных принадлежностей (в кг)
A2: Дата | B2: Вид стирки | C2: Количество | D2: Общее время | E2: EMULSIFIER | F2: ALKALINE | G2: BLEACH | H2: SOFTENER | I2: NEUTRLIZER | J2: Вес | AH2: Всего Вес | AI2: Ваниш | AK2: Ленор | AM2: Порошок
J3: 1 | L3: 2 | N3: 3 | P3: 4 | R3: 5 | T3: 6 | V3: 7 | X3: 8 | Z3: 9 | AB3: 10 | AD3: 11 | AF3: 12
J4: день | K4: ночь | L4: день | M4: ночь | N4: день | O4: ночь | P4: день | Q4: ночь | R4: день | S4: ночь | T4: день | U4: ночь | V4: день | W4: ночь | X4: день | Y4: ночь | Z4: день | AA4: ночь | AB4: день | AC4: ночь | AD4: день | AE4: ночь | AF4: день | AG4: ночь | AI4: Кол-во | AJ4: Общее | AK4: Кол-во | AL4: Общее | AM4: Кол-во | AN4: Общее
B5: Постель белая | C5: =COUNT(J5:AG9) | D5: =C5*57 | E5: =C5*55*3 | F5: =C5*55*8 | G5: =C5*55*6 | H5: =C5*55*4 | I5: =C5*55*1 | AH5: =SUM(J5:AG9) | AJ5: =AI5*5 | AL5: =AK5*50 | AN5: =AM5*175
B10: Махра белая | C10: =COUNT(J10:AG14) | D10: =C10*51 | E10: =C10*55*3 | F10: =C10*55*8 | G10: =C10*55*6 | H10: =C10*55*5 | I10: =C10*55*1 | AH10: =SUM(J10:AG14) | AJ10: =AI10*5 | AL10: =AK10*50 | AN10: =AM10*175
B15: Униформа белая | C15: =COUNT(J15:AG19) | D15: =C15*55 | E15: =C15*55*3 | F15: =C15*55*8 | G15: =C15*55*5 | H15: =C15*55*3 | I15: =C15*55*1 | AH15: =SUM(J15:AG19) | AJ15: =AI15*5 | AL15: =AK15*50 | AN15: =AM15*175
B20: Униформа темная | C20: =COUNT(J20:AG24) | D20: =C20*45 | E20: =C20*55*2 | F20: =C20*55*6 | G20: =C20*55*0 | H20: =C20*55*3 | I20: =C20*55*1 | AH20: =SUM(J20:AG24) | AJ20: =AI20*5 | AL20: =AK20*50 | AN20: =AM20*175
B25: Синтетика | C25: =COUNT(J25:AG29) | D25: =C25*38 | E25: =C25*55*3 | F25: =C25*55*5 | G25: =C25*55*0 | H25: =C25*55*3 | I25: =C25*55*1 | AH25: =SUM(J25:AG29) | AJ25: =AI25*5 | AL25: =AK25*50 | AN25: =AM25*175
B30: Деликатная | C30: =COUNT(J30:AG34) | D30: =C30*50 | E30: =C30*55*2 | F30: =C30*55*4 | G30: =C30*55*0 | H30: =C30*55*3 | I30: =C30*55*1 | AH30: =SUM(J30:AG34) | AJ30: =AI30*5 | AL30: =AK30*50 | AN30: =AM30*175
B35: Спецодежда | C35: =COUNT(J35:AG39) | D35: =C35*42 | E35: =C35*55*3 | F35: =C35*55*10 | G35: =C35*55*0 | H35: =C35*55*3 | I35: =C35*55*1 | AH35: =SUM(J35:AG39) | AJ35: =AI35*5 | AL35: =AK35*50 | AN35: =AM35*175
A40: ИТОГО | C40: =C5+C10+C15+C20+C25+C30+C35 | D40: =D5+D10+D15+D20+D25+D30+D35 | E40: =E5+E10+E15+E20+E25+E30+E35 | F40: =F5+F10+F15+F20+F25+F30+F35 | G40: =G5+G10+G15+G20+G25+G30+G35 | H40: =H5+H10+H15+H20+H25+H30+H35 | I40: =I5+I10+I15+I20+I25+I30+I35 | J40: =J5+J6+J7+J8+J9+J10+J11+J12+J13+J14+J15+J16+J17+J18+J19+J20+J21+J22+J23+J24+J25+J26+J27+J28+J29+J30+J31+J32+J33+J34+J35+J36+J37+J38+J39 | K40: =K5+K6+K7+K8+K9+K10+K11+K12+K13+K14+K15+K16+K17+K18+K19+K20+K21+K22+K23+K24+K25+K26+K27+K28+K29+K30+K31+K32+K33+K34+K35+K36+K37+K38+K39 | L40: =L5+L6+L7+L8+L9+L10+L11+L12+L13+L14+L15+L16+L17+L18+L19+L20+L21+L22+L23+L24+L25+L26+L27+L28+L29+L30+L31+L32+L33+L34+L35+L36+L37+L38+L39 | M40: =M5+M6+M7+M8+M9+M10+M11+M12+M13+M14+M15+M16+M17+M18+M19+M20+M21+M22+M23+M24+M25+M26+M27+M28+M29+M30+M31+M32+M33+M34+M35+M36+M37+M38+M39 | N40: =N5+N6+N7+N8+N9+N10+N11+N12+N13+N14+N15+N16+N17+N18+N19+N20+N21+N22+N23+N24+N25+N26+N27+N28+N29+N30+N31+N32+N33+N34+N35+N36+N37+N38+N39 | O40: =O5+O6+O7+O8+O9+O10+O11+O12+O13+O14+O15+O16+O17+O18+O19+O20+O21+O22+O23+O24+O25+O26+O27+O28+O29+O30+O31+O32+O33+O34+O35+O36+O37+O38+O39 | P40: =P5+P6+P7+P8+P9+P10+P11+P12+P13+P14+P15+P16+P17+P18+P19+P20+P21+P22+P23+P24+P25+P26+P27+P28+P29+P30+P31+P32+P33+P34+P35+P36+P37+P38+P39 | Q40: =Q5+Q6+Q7+Q8+Q9+Q10+Q11+Q12+Q13+Q14+Q15+Q16+Q17+Q18+Q19+Q20+Q21+Q22+Q23+Q24+Q25+Q26+Q27+Q28+Q29+Q30+Q31+Q32+Q33+Q34+Q35+Q36+Q37+Q38+Q39 | ... AG40: =AG5+AG6+AG7+AG8+AG9+AG10+AG11+AG12+AG13+AG14+AG15+AG16+AG17+AG18+AG19+AG20+AG21+AG22+AG23+AG24+AG25+AG26+AG27+AG28+AG29+AG30+AG31+AG32+AG33+AG34+AG35+AG36+AG37+AG38+AG39 | AH40: =AH5+AH10+AH15+AH20+AH25+AH30+AH35 | AI40: =AI5+AI10+AI15+AI20+AI25+AI30+AI35 | AJ40: =AJ5+AJ10+AJ15+AJ20+AJ25+AJ30+AJ35 | AK40: =AK5+AK10+AK15+AK20+AK25+AK30+AK35 | AL40: =AL5+AL10+AL15+AL20+AL25+AL30+AL35 | AM40: =AM5+AM10+AM15+AM20+AM25+AM30+AM35 | AN40: =AN5+AN10+AN15+AN20+AN25+AN30+AN35

Sheet 7
A1: Лист для ежедневной регистрации грязного белья и постельных принадлежностей (в кг)
A2: Дата | B2: Вид стирки | C2: Количество | D2: Общее время | E2: EMULSIFIER | F2: ALKALINE | G2: BLEACH | H2: SOFTENER | I2: NEUTRLIZER | J2: Вес | AH2: Всего Вес | AI2: Ваниш | AK2: Ленор | AM2: Порошок
J3: 1 | L3: 2 | N3: 3 | P3: 4 | R3: 5 | T3: 6 | V3: 7 | X3: 8 | Z3: 9 | AB3: 10 | AD3: 11 | AF3: 12
J4: день | K4: ночь | L4: день | M4: ночь | N4: день | O4: ночь | P4: день | Q4: ночь | R4: день | S4: ночь | T4: день | U4: ночь | V4: день | W4: ночь | X4: день | Y4: ночь | Z4: день | AA4: ночь | AB4: день | AC4: ночь | AD4: день | AE4: ночь | AF4: день | AG4: ночь | AI4: Кол-во | AJ4: Общее | AK4: Кол-во | AL4: Общее | AM4: Кол-во | AN4: Общее
B5: Постель белая | C5: =COUNT(J5:AG9) | D5: =C5*57 | E5: =C5*55*3 | F5: =C5*55*8 | G5: =C5*55*6 | H5: =C5*55*4 | I5: =C5*55*1 | AH5: =SUM(J5:AG9) | AJ5: =AI5*5 | AL5: =AK5*50 | AN5: =AM5*175
B10: Махра белая | C10: =COUNT(J10:AG14) | D10: =C10*51 | E10: =C10*55*3 | F10: =C10*55*8 | G10: =C10*55*6 | H10: =C10*55*5 | I10: =C10*55*1 | AH10: =SUM(J10:AG14) | AJ10: =AI10*5 | AL10: =AK10*50 | AN10: =AM10*175
B15: Униформа белая | C15: =COUNT(J15:AG19) | D15: =C15*55 | E15: =C15*55*3 | F15: =C15*55*8 | G15: =C15*55*5 | H15: =C15*55*3 | I15: =C15*55*1 | AH15: =SUM(J15:AG19) | AJ15: =AI15*5 | AL15: =AK15*50 | AN15: =AM15*175
B20: Униформа темная | C20: =COUNT(J20:AG24) | D20: =C20*45 | E20: =C20*55*2 | F20: =C20*55*6 | G20: =C20*55*0 | H20: =C20*55*3 | I20: =C20*55*1 | AH20: =SUM(J20:AG24) | AJ20: =AI20*5 | AL20: =AK20*50 | AN20: =AM20*175
B25: Синтетика | C25: =COUNT(J25:AG29) | D25: =C25*38 | E25: =C25*55*3 | F25: =C25*55*5 | G25: =C25*55*0 | H25: =C25*55*3 | I25: =C25*55*1 | AH25: =SUM(J25:AG29) | AJ25: =AI25*5 | AL25: =AK25*50 | AN25: =AM25*175
B30: Деликатная | C30: =COUNT(J30:AG34) | D30: =C30*50 | E30: =C30*55*2 | F30: =C30*55*4 | G30: =C30*55*0 | H30: =C30*55*3 | I30: =C30*55*1 | AH30: =SUM(J30:AG34) | AJ30: =AI30*5 | AL30: =AK30*50 | AN30: =AM30*175
B35: Спецодежда | C35: =COUNT(J35:AG39) | D35: =C35*42 | E35: =C35*55*3 | F35: =C35*55*10 | G35: =C35*55*0 | H35: =C35*55*3 | I35: =C35*55*1 | AH35: =SUM(J35:AG39) | AJ35: =AI35*5 | AL35: =AK35*50 | AN35: =AM35*175
A40: ИТОГО | C40: =C5+C10+C15+C20+C25+C30+C35 | D40: =D5+D10+D15+D20+D25+D30+D35 | E40: =E5+E10+E15+E20+E25+E30+E35 | F40: =F5+F10+F15+F20+F25+F30+F35 | G40: =G5+G10+G15+G20+G25+G30+G35 | H40: =H5+H10+H15+H20+H25+H30+H35 | I40: =I5+I10+I15+I20+I25+I30+I35 | J40: =J5+J6+J7+J8+J9+J10+J11+J12+J13+J14+J15+J16+J17+J18+J19+J20+J21+J22+J23+J24+J25+J26+J27+J28+J29+J30+J31+J32+J33+J34+J35+J36+J37+J38+J39 | K40: =K5+K6+K7+K8+K9+K10+K11+K12+K13+K14+K15+K16+K17+K18+K19+K20+K21+K22+K23+K24+K25+K26+K27+K28+K29+K30+K31+K32+K33+K34+K35+K36+K37+K38+K39 | L40: =L5+L6+L7+L8+L9+L10+L11+L12+L13+L14+L15+L16+L17+L18+L19+L20+L21+L22+L23+L24+L25+L26+L27+L28+L29+L30+L31+L32+L33+L34+L35+L36+L37+L38+L39 | M40: =M5+M6+M7+M8+M9+M10+M11+M12+M13+M14+M15+M16+M17+M18+M19+M20+M21+M22+M23+M24+M25+M26+M27+M28+M29+M30+M31+M32+M33+M34+M35+M36+M37+M38+M39 | N40: =N5+N6+N7+N8+N9+N10+N11+N12+N13+N14+N15+N16+N17+N18+N19+N20+N21+N22+N23+N24+N25+N26+N27+N28+N29+N30+N31+N32+N33+N34+N35+N36+N37+N38+N39 | O40: =O5+O6+O7+O8+O9+O10+O11+O12+O13+O14+O15+O16+O17+O18+O19+O20+O21+O22+O23+O24+O25+O26+O27+O28+O29+O30+O31+O32+O33+O34+O35+O36+O37+O38+O39 | P40: =P5+P6+P7+P8+P9+P10+P11+P12+P13+P14+P15+P16+P17+P18+P19+P20+P21+P22+P23+P24+P25+P26+P27+P28+P29+P30+P31+P32+P33+P34+P35+P36+P37+P38+P39 | Q40: =Q5+Q6+Q7+Q8+Q9+Q10+Q11+Q12+Q13+Q14+Q15+Q16+Q17+Q18+Q19+Q20+Q21+Q22+Q23+Q24+Q25+Q26+Q27+Q28+Q29+Q30+Q31+Q32+Q33+Q34+Q35+Q36+Q37+Q38+Q39 | ... AG40: =AG5+AG6+AG7+AG8+AG9+AG10+AG11+AG12+AG13+AG14+AG15+AG16+AG17+AG18+AG19+AG20+AG21+AG22+AG23+AG24+AG25+AG26+AG27+AG28+AG29+AG30+AG31+AG32+AG33+AG34+AG35+AG36+AG37+AG38+AG39 | AH40: =AH5+AH10+AH15+AH20+AH25+AH30+AH35 | AI40: =AI5+AI10+AI15+AI20+AI25+AI30+AI35 | AJ40: =AJ5+AJ10+AJ15+AJ20+AJ25+AJ30+AJ35 | AK40: =AK5+AK10+AK15+AK20+AK25+AK30+AK35 | AL40: =AL5+AL10+AL15+AL20+AL25+AL30+AL35 | AM40: =AM5+AM10+AM15+AM20+AM25+AM30+AM35 | AN40: =AN5+AN10+AN15+AN20+AN25+AN30+AN35

Sheet 8
A1: Лист для ежедневной регистрации грязного белья и постельных принадлежностей (в кг)
A2: Дата | B2: Вид стирки | C2: Количество | D2: Общее время | E2: EMULSIFIER | F2: ALKALINE | G2: BLEACH | H2: SOFTENER | I2: NEUTRLIZER | J2: Вес | AH2: Всего Вес | AI2: Ваниш | AK2: Ленор | AM2: Порошок
J3: 1 | L3: 2 | N3: 3 | P3: 4 | R3: 5 | T3: 6 | V3: 7 | X3: 8 | Z3: 9 | AB3: 10 | AD3: 11 | AF3: 12
J4: день | K4: ночь | L4: день | M4: ночь | N4: день | O4: ночь | P4: день | Q4: ночь | R4: день | S4: ночь | T4: день | U4: ночь | V4: день | W4: ночь | X4: день | Y4: ночь | Z4: день | AA4: ночь | AB4: день | AC4: ночь | AD4: день | AE4: ночь | AF4: день | AG4: ночь | AI4: Кол-во | AJ4: Общее | AK4: Кол-во | AL4: Общее | AM4: Кол-во | AN4: Общее
B5: Постель белая | C5: =COUNT(J5:AG9) | D5: =C5*57 | E5: =C5*55*3 | F5: =C5*55*8 | G5: =C5*55*6 | H5: =C5*55*4 | I5: =C5*55*1 | AH5: =SUM(J5:AG9) | AJ5: =AI5*5 | AL5: =AK5*50 | AN5: =AM5*175
B10: Махра белая | C10: =COUNT(J10:AG14) | D10: =C10*51 | E10: =C10*55*3 | F10: =C10*55*8 | G10: =C10*55*6 | H10: =C10*55*5 | I10: =C10*55*1 | AH10: =SUM(J10:AG14) | AJ10: =AI10*5 | AL10: =AK10*50 | AN10: =AM10*175
B15: Униформа белая | C15: =COUNT(J15:AG19) | D15: =C15*55 | E15: =C15*55*3 | F15: =C15*55*8 | G15: =C15*55*5 | H15: =C15*55*3 | I15: =C15*55*1 | AH15: =SUM(J15:AG19) | AJ15: =AI15*5 | AL15: =AK15*50 | AN15: =AM15*175
B20: Униформа темная | C20: =COUNT(J20:AG24) | D20: =C20*45 | E20: =C20*55*2 | F20: =C20*55*6 | G20: =C20*55*0 | H20: =C20*55*3 | I20: =C20*55*1 | AH20: =SUM(J20:AG24) | AJ20: =AI20*5 | AL20: =AK20*50 | AN20: =AM20*175
B25: Синтетика | C25: =COUNT(J25:AG29) | D25: =C25*38 | E25: =C25*55*3 | F25: =C25*55*5 | G25: =C25*55*0 | H25: =C25*55*3 | I25: =C25*55*1 | AH25: =SUM(J25:AG29) | AJ25: =AI25*5 | AL25: =AK25*50 | AN25: =AM25*175
B30: Деликатная | C30: =COUNT(J30:AG34) | D30: =C30*50 | E30: =C30*55*2 | F30: =C30*55*4 | G30: =C30*55*0 | H30: =C30*55*3 | I30: =C30*55*1 | AH30: =SUM(J30:AG34) | AJ30: =AI30*5 | AL30: =AK30*50 | AN30: =AM30*175
B35: Спецодежда | C35: =COUNT(J35:AG39) | D35: =C35*42 | E35: =C35*55*3 | F35: =C35*55*10 | G35: =C35*55*0 | H35: =C35*55*3 | I35: =C35*55*1 | AH35: =SUM(J35:AG39) | AJ35: =AI35*5 | AL35: =AK35*50 | AN35: =AM35*175
A40: ИТОГО | C40: =C5+C10+C15+C20+C25+C30+C35 | D40: =D5+D10+D15+D20+D25+D30+D35 | E40: =E5+E10+E15+E20+E25+E30+E35 | F40: =F5+F10+F15+F20+F25+F30+F35 | G40: =G5+G10+G15+G20+G25+G30+G35 | H40: =H5+H10+H15+H20+H25+H30+H35 | I40: =I5+I10+I15+I20+I25+I30+I35 | J40: =J5+J6+J7+J8+J9+J10+J11+J12+J13+J14+J15+J16+J17+J18+J19+J20+J21+J22+J23+J24+J25+J26+J27+J28+J29+J30+J31+J32+J33+J34+J35+J36+J37+J38+J39 | K40: =K5+K6+K7+K8+K9+K10+K11+K12+K13+K14+K15+K16+K17+K18+K19+K20+K21+K22+K23+K24+K25+K26+K27+K28+K29+K30+K31+K32+K33+K34+K35+K36+K37+K38+K39 | L40: =L5+L6+L7+L8+L9+L10+L11+L12+L13+L14+L15+L16+L17+L18+L19+L20+L21+L22+L23+L24+L25+L26+L27+L28+L29+L30+L31+L32+L33+L34+L35+L36+L37+L38+L39 | M40: =M5+M6+M7+M8+M9+M10+M11+M12+M13+M14+M15+M16+M17+M18+M19+M20+M21+M22+M23+M24+M25+M26+M27+M28+M29+M30+M31+M32+M33+M34+M35+M36+M37+M38+M39 | N40: =N5+N6+N7+N8+N9+N10+N11+N12+N13+N14+N15+N16+N17+N18+N19+N20+N21+N22+N23+N24+N25+N26+N27+N28+N29+N30+N31+N32+N33+N34+N35+N36+N37+N38+N39 | O40: =O5+O6+O7+O8+O9+O10+O11+O12+O13+O14+O15+O16+O17+O18+O19+O20+O21+O22+O23+O24+O25+O26+O27+O28+O29+O30+O31+O32+O33+O34+O35+O36+O37+O38+O39 | P40: =P5+P6+P7+P8+P9+P10+P11+P12+P13+P14+P15+P16+P17+P18+P19+P20+P21+P22+P23+P24+P25+P26+P27+P28+P29+P30+P31+P32+P33+P34+P35+P36+P37+P38+P39 | Q40: =Q5+Q6+Q7+Q8+Q9+Q10+Q11+Q12+Q13+Q14+Q15+Q16+Q17+Q18+Q19+Q20+Q21+Q22+Q23+Q24+Q25+Q26+Q27+Q28+Q29+Q30+Q31+Q32+Q33+Q34+Q35+Q36+Q37+Q38+Q39 | ... AG40: =AG5+AG6+AG7+AG8+AG9+AG10+AG11+AG12+AG13+AG14+AG15+AG16+AG17+AG18+AG19+AG20+AG21+AG22+AG23+AG24+AG25+AG26+AG27+AG28+AG29+AG30+AG31+AG32+AG33+AG34+AG35+AG36+AG37+AG38+AG39 | AH40: =AH5+AH10+AH15+AH20+AH25+AH30+AH35 | AI40: =AI5+AI10+AI15+AI20+AI25+AI30+AI35 | AJ40: =AJ5+AJ10+AJ15+AJ20+AJ25+AJ30+AJ35 | AK40: =AK5+AK10+AK15+AK20+AK25+AK30+AK35 | AL40: =AL5+AL10+AL15+AL20+AL25+AL30+AL35 | AM40: =AM5+AM10+AM15+AM20+AM25+AM30+AM35 | AN40: =AN5+AN10+AN15+AN20+AN25+AN30+AN35

Sheet 9
A1: Лист для ежедневной регистрации грязного белья и постельных принадлежностей (в кг)
A2: Дата | B2: Вид стирки | C2: Количество | D2: Общее время | E2: EMULSIFIER | F2: ALKALINE | G2: BLEACH | H2: SOFTENER | I2: NEUTRLIZER | J2: Вес | AH2: Всего Вес | AI2: Ваниш | AK2: Ленор | AM2: Порошок
J3: 1 | L3: 2 | N3: 3 | P3: 4 | R3: 5 | T3: 6 | V3: 7 | X3: 8 | Z3: 9 | AB3: 10 | AD3: 11 | AF3: 12
J4: день | K4: ночь | L4: день | M4: ночь | N4: день | O4: ночь | P4: день | Q4: ночь | R4: день | S4: ночь | T4: день | U4: ночь | V4: день | W4: ночь | X4: день | Y4: ночь | Z4: день | AA4: ночь | AB4: день | AC4: ночь | AD4: день | AE4: ночь | AF4: день | AG4: ночь | AI4: Кол-во | AJ4: Общее | AK4: Кол-во | AL4: Общее | AM4: Кол-во | AN4: Общее
B5: Постель белая | C5: =COUNT(J5:AG9) | D5: =C5*57 | E5: =C5*55*3 | F5: =C5*55*8 | G5: =C5*55*6 | H5: =C5*55*4 | I5: =C5*55*1 | AH5: =SUM(J5:AG9) | AJ5: =AI5*5 | AL5: =AK5*50 | AN5: =AM5*175
B10: Махра белая | C10: =COUNT(J10:AG14) | D10: =C10*51 | E10: =C10*55*3 | F10: =C10*55*8 | G10: =C10*55*6 | H10: =C10*55*5 | I10: =C10*55*1 | AH10: =SUM(J10:AG14) | AJ10: =AI10*5 | AL10: =AK10*50 | AN10: =AM10*175
B15: Униформа белая | C15: =COUNT(J15:AG19) | D15: =C15*55 | E15: =C15*55*3 | F15: =C15*55*8 | G15: =C15*55*5 | H15: =C15*55*3 | I15: =C15*55*1 | AH15: =SUM(J15:AG19) | AJ15: =AI15*5 | AL15: =AK15*50 | AN15: =AM15*175
B20: Униформа темная | C20: =COUNT(J20:AG24) | D20: =C20*45 | E20: =C20*55*2 | F20: =C20*55*6 | G20: =C20*55*0 | H20: =C20*55*3 | I20: =C20*55*1 | AH20: =SUM(J20:AG24) | AJ20: =AI20*5 | AL20: =AK20*50 | AN20: =AM20*175
B25: Синтетика | C25: =COUNT(J25:AG29) | D25: =C25*38 | E25: =C25*55*3 | F25: =C25*55*5 | G25: =C25*55*0 | H25: =C25*55*3 | I25: =C25*55*1 | AH25: =SUM(J25:AG29) | AJ25: =AI25*5 | AL25: =AK25*50 | AN25: =AM25*175
B30: Деликатная | C30: =COUNT(J30:AG34) | D30: =C30*50 | E30: =C30*55*2 | F30: =C30*55*4 | G30: =C30*55*0 | H30: =C30*55*3 | I30: =C30*55*1 | AH30: =SUM(J30:AG34) | AJ30: =AI30*5 | AL30: =AK30*50 | AN30: =AM30*175
B35: Спецодежда | C35: =COUNT(J35:AG39) | D35: =C35*42 | E35: =C35*55*3 | F35: =C35*55*10 | G35: =C35*55*0 | H35: =C35*55*3 | I35: =C35*55*1 | AH35: =SUM(J35:AG39) | AJ35: =AI35*5 | AL35: =AK35*50 | AN35: =AM35*175
A40: ИТОГО | C40: =C5+C10+C15+C20+C25+C30+C35 | D40: =D5+D10+D15+D20+D25+D30+D35 | E40: =E5+E10+E15+E20+E25+E30+E35 | F40: =F5+F10+F15+F20+F25+F30+F35 | G40: =G5+G10+G15+G20+G25+G30+G35 | H40: =H5+H10+H15+H20+H25+H30+H35 | I40: =I5+I10+I15+I20+I25+I30+I35 | J40: =J5+J6+J7+J8+J9+J10+J11+J12+J13+J14+J15+J16+J17+J18+J19+J20+J21+J22+J23+J24+J25+J26+J27+J28+J29+J30+J31+J32+J33+J34+J35+J36+J37+J38+J39 | K40: =K5+K6+K7+K8+K9+K10+K11+K12+K13+K14+K15+K16+K17+K18+K19+K20+K21+K22+K23+K24+K25+K26+K27+K28+K29+K30+K31+K32+K33+K34+K35+K36+K37+K38+K39 | L40: =L5+L6+L7+L8+L9+L10+L11+L12+L13+L14+L15+L16+L17+L18+L19+L20+L21+L22+L23+L24+L25+L26+L27+L28+L29+L30+L31+L32+L33+L34+L35+L36+L37+L38+L39 | M40: =M5+M6+M7+M8+M9+M10+M11+M12+M13+M14+M15+M16+M17+M18+M19+M20+M21+M22+M23+M24+M25+M26+M27+M28+M29+M30+M31+M32+M33+M34+M35+M36+M37+M38+M39 | N40: =N5+N6+N7+N8+N9+N10+N11+N12+N13+N14+N15+N16+N17+N18+N19+N20+N21+N22+N23+N24+N25+N26+N27+N28+N29+N30+N31+N32+N33+N34+N35+N36+N37+N38+N39 | O40: =O5+O6+O7+O8+O9+O10+O11+O12+O13+O14+O15+O16+O17+O18+O19+O20+O21+O22+O23+O24+O25+O26+O27+O28+O29+O30+O31+O32+O33+O34+O35+O36+O37+O38+O39 | P40: =P5+P6+P7+P8+P9+P10+P11+P12+P13+P14+P15+P16+P17+P18+P19+P20+P21+P22+P23+P24+P25+P26+P27+P28+P29+P30+P31+P32+P33+P34+P35+P36+P37+P38+P39 | Q40: =Q5+Q6+Q7+Q8+Q9+Q10+Q11+Q12+Q13+Q14+Q15+Q16+Q17+Q18+Q19+Q20+Q21+Q22+Q23+Q24+Q25+Q26+Q27+Q28+Q29+Q30+Q31+Q32+Q33+Q34+Q35+Q36+Q37+Q38+Q39 | ... AG40: =AG5+AG6+AG7+AG8+AG9+AG10+AG11+AG12+AG13+AG14+AG15+AG16+AG17+AG18+AG19+AG20+AG21+AG22+AG23+AG24+AG25+AG26+AG27+AG28+AG29+AG30+AG31+AG32+AG33+AG34+AG35+AG36+AG37+AG38+AG39 | AH40: =AH5+AH10+AH15+AH20+AH25+AH30+AH35 | AI40: =AI5+AI10+AI15+AI20+AI25+AI30+AI35 | AJ40: =AJ5+AJ10+AJ15+AJ20+AJ25+AJ30+AJ35 | AK40: =AK5+AK10+AK15+AK20+AK25+AK30+AK35 | AL40: =AL5+AL10+AL15+AL20+AL25+AL30+AL35 | AM40: =AM5+AM10+AM15+AM20+AM25+AM30+AM35 | AN40: =AN5+AN10+AN15+AN20+AN25+AN30+AN35

Sheet 10
A1: Лист для ежедневной регистрации грязного белья и постельных принадлежностей (в кг)
A2: Дата | B2: Вид стирки | C2: Количество | D2: Общее время | E2: EMULSIFIER | F2: ALKALINE | G2: BLEACH | H2: SOFTENER | I2: NEUTRLIZER | J2: Вес | AH2: Всего Вес | AI2: Ваниш | AK2: Ленор | AM2: Порошок
J3: 1 | L3: 2 | N3: 3 | P3: 4 | R3: 5 | T3: 6 | V3: 7 | X3: 8 | Z3: 9 | AB3: 10 | AD3: 11 | AF3: 12
J4: день | K4: ночь | L4: день | M4: ночь | N4: день | O4: ночь | P4: день | Q4: ночь | R4: день | S4: ночь | T4: день | U4: ночь | V4: день | W4: ночь | X4: день | Y4: ночь | Z4: день | AA4: ночь | AB4: день | AC4: ночь | AD4: день | AE4: ночь | AF4: день | AG4: ночь | AI4: Кол-во | AJ4: Общее | AK4: Кол-во | AL4: Общее | AM4: Кол-во | AN4: Общее
B5: Постель белая | C5: =COUNT(J5:AG9) | D5: =C5*57 | E5: =C5*55*3 | F5: =C5*55*8 | G5: =C5*55*6 | H5: =C5*55*4 | I5: =C5*55*1 | AH5: =SUM(J5:AG9) | AJ5: =AI5*5 | AL5: =AK5*50 | AN5: =AM5*175
B10: Махра белая | C10: =COUNT(J10:AG14) | D10: =C10*51 | E10: =C10*55*3 | F10: =C10*55*8 | G10: =C10*55*6 | H10: =C10*55*5 | I10: =C10*55*1 | AH10: =SUM(J10:AG14) | AJ10: =AI10*5 | AL10: =AK10*50 | AN10: =AM10*175
B15: Униформа белая | C15: =COUNT(J15:AG19) | D15: =C15*55 | E15: =C15*55*3 | F15: =C15*55*8 | G15: =C15*55*5 | H15: =C15*55*3 | I15: =C15*55*1 | AH15: =SUM(J15:AG19) | AJ15: =AI15*5 | AL15: =AK15*50 | AN15: =AM15*175
B20: Униформа темная | C20: =COUNT(J20:AG24) | D20: =C20*45 | E20: =C20*55*2 | F20: =C20*55*6 | G20: =C20*55*0 | H20: =C20*55*3 | I20: =C20*55*1 | AH20: =SUM(J20:AG24) | AJ20: =AI20*5 | AL20: =AK20*50 | AN20: =AM20*175
B25: Синтетика | C25: =COUNT(J25:AG29) | D25: =C25*38 | E25: =C25*55*3 | F25: =C25*55*5 | G25: =C25*55*0 | H25: =C25*55*3 | I25: =C25*55*1 | AH25: =SUM(J25:AG29) | AJ25: =AI25*5 | AL25: =AK25*50 | AN25: =AM25*175
B30: Деликатная | C30: =COUNT(J30:AG34) | D30: =C30*50 | E30: =C30*55*2 | F30: =C30*55*4 | G30: =C30*55*0 | H30: =C30*55*3 | I30: =C30*55*1 | AH30: =SUM(J30:AG34) | AJ30: =AI30*5 | AL30: =AK30*50 | AN30: =AM30*175
B35: Спецодежда | C35: =COUNT(J35:AG39) | D35: =C35*42 | E35: =C35*55*3 | F35: =C35*55*10 | G35: =C35*55*0 | H35: =C35*55*3 | I35: =C35*55*1 | AH35: =SUM(J35:AG39) | AJ35: =AI35*5 | AL35: =AK35*50 | AN35: =AM35*175
A40: ИТОГО | C40: =C5+C10+C15+C20+C25+C30+C35 | D40: =D5+D10+D15+D20+D25+D30+D35 | E40: =E5+E10+E15+E20+E25+E30+E35 | F40: =F5+F10+F15+F20+F25+F30+F35 | G40: =G5+G10+G15+G20+G25+G30+G35 | H40: =H5+H10+H15+H20+H25+H30+H35 | I40: =I5+I10+I15+I20+I25+I30+I35 | J40: =J5+J6+J7+J8+J9+J10+J11+J12+J13+J14+J15+J16+J17+J18+J19+J20+J21+J22+J23+J24+J25+J26+J27+J28+J29+J30+J31+J32+J33+J34+J35+J36+J37+J38+J39 | K40: =K5+K6+K7+K8+K9+K10+K11+K12+K13+K14+K15+K16+K17+K18+K19+K20+K21+K22+K23+K24+K25+K26+K27+K28+K29+K30+K31+K32+K33+K34+K35+K36+K37+K38+K39 | L40: =L5+L6+L7+L8+L9+L10+L11+L12+L13+L14+L15+L16+L17+L18+L19+L20+L21+L22+L23+L24+L25+L26+L27+L28+L29+L30+L31+L32+L33+L34+L35+L36+L37+L38+L39 | M40: =M5+M6+M7+M8+M9+M10+M11+M12+M13+M14+M15+M16+M17+M18+M19+M20+M21+M22+M23+M24+M25+M26+M27+M28+M29+M30+M31+M32+M33+M34+M35+M36+M37+M38+M39 | N40: =N5+N6+N7+N8+N9+N10+N11+N12+N13+N14+N15+N16+N17+N18+N19+N20+N21+N22+N23+N24+N25+N26+N27+N28+N29+N30+N31+N32+N33+N34+N35+N36+N37+N38+N39 | O40: =O5+O6+O7+O8+O9+O10+O11+O12+O13+O14+O15+O16+O17+O18+O19+O20+O21+O22+O23+O24+O25+O26+O27+O28+O29+O30+O31+O32+O33+O34+O35+O36+O37+O38+O39 | P40: =P5+P6+P7+P8+P9+P10+P11+P12+P13+P14+P15+P16+P17+P18+P19+P20+P21+P22+P23+P24+P25+P26+P27+P28+P29+P30+P31+P32+P33+P34+P35+P36+P37+P38+P39 | Q40: =Q5+Q6+Q7+Q8+Q9+Q10+Q11+Q12+Q13+Q14+Q15+Q16+Q17+Q18+Q19+Q20+Q21+Q22+Q23+Q24+Q25+Q26+Q27+Q28+Q29+Q30+Q31+Q32+Q33+Q34+Q35+Q36+Q37+Q38+Q39 | ... AG40: =AG5+AG6+AG7+AG8+AG9+AG10+AG11+AG12+AG13+AG14+AG15+AG16+AG17+AG18+AG19+AG20+AG21+AG22+AG23+AG24+AG25+AG26+AG27+AG28+AG29+AG30+AG31+AG32+AG33+AG34+AG35+AG36+AG37+AG38+AG39 | AH40: =AH5+AH10+AH15+AH20+AH25+AH30+AH35 | AI40: =AI5+AI10+AI15+AI20+AI25+AI30+AI35 | AJ40: =AJ5+AJ10+AJ15+AJ20+AJ25+AJ30+AJ35 | AK40: =AK5+AK10+AK15+AK20+AK25+AK30+AK35 | AL40: =AL5+AL10+AL15+AL20+AL25+AL30+AL35 | AM40: =AM5+AM10+AM15+AM20+AM25+AM30+AM35 | AN40: =AN5+AN10+AN15+AN20+AN25+AN30+AN35

Sheet 11
A1: Лист для ежедневной регистрации грязного белья и постельных принадлежностей (в кг)
A2: Дата | B2: Вид стирки | C2: Количество | D2: Общее время | E2: EMULSIFIER | F2: ALKALINE | G2: BLEACH | H2: SOFTENER | I2: NEUTRLIZER | J2: Вес | AH2: Всего Вес | AI2: Ваниш | AK2: Ленор | AM2: Порошок
J3: 1 | L3: 2 | N3: 3 | P3: 4 | R3: 5 | T3: 6 | V3: 7 | X3: 8 | Z3: 9 | AB3: 10 | AD3: 11 | AF3: 12
J4: день | K4: ночь | L4: день | M4: ночь | N4: день | O4: ночь | P4: день | Q4: ночь | R4: день | S4: ночь | T4: день | U4: ночь | V4: день | W4: ночь | X4: день | Y4: ночь | Z4: день | AA4: ночь | AB4: день | AC4: ночь | AD4: день | AE4: ночь | AF4: день | AG4: ночь | AI4: Кол-во | AJ4: Общее | AK4: Кол-во | AL4: Общее | AM4: Кол-во | AN4: Общее
B5: Постель белая | C5: =COUNT(J5:AG9) | D5: =C5*57 | E5: =C5*55*3 | F5: =C5*55*8 | G5: =C5*55*6 | H5: =C5*55*4 | I5: =C5*55*1 | AH5: =SUM(J5:AG9) | AJ5: =AI5*5 | AL5: =AK5*50 | AN5: =AM5*175
B10: Махра белая | C10: =COUNT(J10:AG14) | D10: =C10*51 | E10: =C10*55*3 | F10: =C10*55*8 | G10: =C10*55*6 | H10: =C10*55*5 | I10: =C10*55*1 | AH10: =SUM(J10:AG14) | AJ10: =AI10*5 | AL10: =AK10*50 | AN10: =AM10*175
B15: Униформа белая | C15: =COUNT(J15:AG19) | D15: =C15*55 | E15: =C15*55*3 | F15: =C15*55*8 | G15: =C15*55*5 | H15: =C15*55*3 | I15: =C15*55*1 | AH15: =SUM(J15:AG19) | AJ15: =AI15*5 | AL15: =AK15*50 | AN15: =AM15*175
B20: Униформа темная | C20: =COUNT(J20:AG24) | D20: =C20*45 | E20: =C20*55*2 | F20: =C20*55*6 | G20: =C20*55*0 | H20: =C20*55*3 | I20: =C20*55*1 | AH20: =SUM(J20:AG24) | AJ20: =AI20*5 | AL20: =AK20*50 | AN20: =AM20*175
B25: Синтетика | C25: =COUNT(J25:AG29) | D25: =C25*38 | E25: =C25*55*3 | F25: =C25*55*5 | G25: =C25*55*0 | H25: =C25*55*3 | I25: =C25*55*1 | AH25: =SUM(J25:AG29) | AJ25: =AI25*5 | AL25: =AK25*50 | AN25: =AM25*175
B30: Деликатная | C30: =COUNT(J30:AG34) | D30: =C30*50 | E30: =C30*55*2 | F30: =C30*55*4 | G30: =C30*55*0 | H30: =C30*55*3 | I30: =C30*55*1 | AH30: =SUM(J30:AG34) | AJ30: =AI30*5 | AL30: =AK30*50 | AN30: =AM30*175
B35: Спецодежда | C35: =COUNT(J35:AG39) | D35: =C35*42 | E35: =C35*55*3 | F35: =C35*55*10 | G35: =C35*55*0 | H35: =C35*55*3 | I35: =C35*55*1 | AH35: =SUM(J35:AG39) | AJ35: =AI35*5 | AL35: =AK35*50 | AN35: =AM35*175
A40: ИТОГО | C40: =C5+C10+C15+C20+C25+C30+C35 | D40: =D5+D10+D15+D20+D25+D30+D35 | E40: =E5+E10+E15+E20+E25+E30+E35 | F40: =F5+F10+F15+F20+F25+F30+F35 | G40: =G5+G10+G15+G20+G25+G30+G35 | H40: =H5+H10+H15+H20+H25+H30+H35 | I40: =I5+I10+I15+I20+I25+I30+I35 | J40: =J5+J6+J7+J8+J9+J10+J11+J12+J13+J14+J15+J16+J17+J18+J19+J20+J21+J22+J23+J24+J25+J26+J27+J28+J29+J30+J31+J32+J33+J34+J35+J36+J37+J38+J39 | K40: =K5+K6+K7+K8+K9+K10+K11+K12+K13+K14+K15+K16+K17+K18+K19+K20+K21+K22+K23+K24+K25+K26+K27+K28+K29+K30+K31+K32+K33+K34+K35+K36+K37+K38+K39 | L40: =L5+L6+L7+L8+L9+L10+L11+L12+L13+L14+L15+L16+L17+L18+L19+L20+L21+L22+L23+L24+L25+L26+L27+L28+L29+L30+L31+L32+L33+L34+L35+L36+L37+L38+L39 | M40: =M5+M6+M7+M8+M9+M10+M11+M12+M13+M14+M15+M16+M17+M18+M19+M20+M21+M22+M23+M24+M25+M26+M27+M28+M29+M30+M31+M32+M33+M34+M35+M36+M37+M38+M39 | N40: =N5+N6+N7+N8+N9+N10+N11+N12+N13+N14+N15+N16+N17+N18+N19+N20+N21+N22+N23+N24+N25+N26+N27+N28+N29+N30+N31+N32+N33+N34+N35+N36+N37+N38+N39 | O40: =O5+O6+O7+O8+O9+O10+O11+O12+O13+O14+O15+O16+O17+O18+O19+O20+O21+O22+O23+O24+O25+O26+O27+O28+O29+O30+O31+O32+O33+O34+O35+O36+O37+O38+O39 | P40: =P5+P6+P7+P8+P9+P10+P11+P12+P13+P14+P15+P16+P17+P18+P19+P20+P21+P22+P23+P24+P25+P26+P27+P28+P29+P30+P31+P32+P33+P34+P35+P36+P37+P38+P39 | Q40: =Q5+Q6+Q7+Q8+Q9+Q10+Q11+Q12+Q13+Q14+Q15+Q16+Q17+Q18+Q19+Q20+Q21+Q22+Q23+Q24+Q25+Q26+Q27+Q28+Q29+Q30+Q31+Q32+Q33+Q34+Q35+Q36+Q37+Q38+Q39 | ... AG40: =AG5+AG6+AG7+AG8+AG9+AG10+AG11+AG12+AG13+AG14+AG15+AG16+AG17+AG18+AG19+AG20+AG21+AG22+AG23+AG24+AG25+AG26+AG27+AG28+AG29+AG30+AG31+AG32+AG33+AG34+AG35+AG36+AG37+AG38+AG39 | AH40: =AH5+AH10+AH15+AH20+AH25+AH30+AH35 | AI40: =AI5+AI10+AI15+AI20+AI25+AI30+AI35 | AJ40: =AJ5+AJ10+AJ15+AJ20+AJ25+AJ30+AJ35 | AK40: =AK5+AK10+AK15+AK20+AK25+AK30+AK35 | AL40: =AL5+AL10+AL15+AL20+AL25+AL30+AL35 | AM40: =AM5+AM10+AM15+AM20+AM25+AM30+AM35 | AN40: =AN5+AN10+AN15+AN20+AN25+AN30+AN35

Sheet 12
A1: Лист для ежедневной регистрации грязного белья и постельных принадлежностей (в кг)
A2: Дата | B2: Вид стирки | C2: Количество | D2: Общее время | E2: EMULSIFIER | F2: ALKALINE | G2: BLEACH | H2: SOFTENER | I2: NEUTRLIZER | J2: Вес | AH2: Всего Вес | AI2: Ваниш | AK2: Ленор | AM2: Порошок
J3: 1 | L3: 2 | N3: 3 | P3: 4 | R3: 5 | T3: 6 | V3: 7 | X3: 8 | Z3: 9 | AB3: 10 | AD3: 11 | AF3: 12
J4: день | K4: ночь | L4: день | M4: ночь | N4: день | O4: ночь | P4: день | Q4: ночь | R4: день | S4: ночь | T4: день | U4: ночь | V4: день | W4: ночь | X4: день | Y4: ночь | Z4: день | AA4: ночь | AB4: день | AC4: ночь | AD4: день | AE4: ночь | AF4: день | AG4: ночь | AI4: Кол-во | AJ4: Общее | AK4: Кол-во | AL4: Общее | AM4: Кол-во | AN4: Общее
B5: Постель белая | C5: =COUNT(J5:AG9) | D5: =C5*57 | E5: =C5*55*3 | F5: =C5*55*8 | G5: =C5*55*6 | H5: =C5*55*4 | I5: =C5*55*1 | AH5: =SUM(J5:AG9) | AJ5: =AI5*5 | AL5: =AK5*50 | AN5: =AM5*175
B10: Махра белая | C10: =COUNT(J10:AG14) | D10: =C10*51 | E10: =C10*55*3 | F10: =C10*55*8 | G10: =C10*55*6 | H10: =C10*55*5 | I10: =C10*55*1 | AH10: =SUM(J10:AG14) | AJ10: =AI10*5 | AL10: =AK10*50 | AN10: =AM10*175
B15: Униформа белая | C15: =COUNT(J15:AG19) | D15: =C15*55 | E15: =C15*55*3 | F15: =C15*55*8 | G15: =C15*55*5 | H15: =C15*55*3 | I15: =C15*55*1 | AH15: =SUM(J15:AG19) | AJ15: =AI15*5 | AL15: =AK15*50 | AN15: =AM15*175
B20: Униформа темная | C20: =COUNT(J20:AG24) | D20: =C20*45 | E20: =C20*55*2 | F20: =C20*55*6 | G20: =C20*55*0 | H20: =C20*55*3 | I20: =C20*55*1 | AH20: =SUM(J20:AG24) | AJ20: =AI20*5 | AL20: =AK20*50 | AN20: =AM20*175
B25: Синтетика | C25: =COUNT(J25:AG29) | D25: =C25*38 | E25: =C25*55*3 | F25: =C25*55*5 | G25: =C25*55*0 | H25: =C25*55*3 | I25: =C25*55*1 | AH25: =SUM(J25:AG29) | AJ25: =AI25*5 | AL25: =AK25*50 | AN25: =AM25*175
B30: Деликатная | C30: =COUNT(J30:AG34) | D30: =C30*50 | E30: =C30*55*2 | F30: =C30*55*4 | G30: =C30*55*0 | H30: =C30*55*3 | I30: =C30*55*1 | AH30: =SUM(J30:AG34) | AJ30: =AI30*5 | AL30: =AK30*50 | AN30: =AM30*175
B35: Спецодежда | C35: =COUNT(J35:AG39) | D35: =C35*42 | E35: =C35*55*3 | F35: =C35*55*10 | G35: =C35*55*0 | H35: =C35*55*3 | I35: =C35*55*1 | AH35: =SUM(J35:AG39) | AJ35: =AI35*5 | AL35: =AK35*50 | AN35: =AM35*175
A40: ИТОГО | C40: =C5+C10+C15+C20+C25+C30+C35 | D40: =D5+D10+D15+D20+D25+D30+D35 | E40: =E5+E10+E15+E20+E25+E30+E35 | F40: =F5+F10+F15+F20+F25+F30+F35 | G40: =G5+G10+G15+G20+G25+G30+G35 | H40: =H5+H10+H15+H20+H25+H30+H35 | I40: =I5+I10+I15+I20+I25+I30+I35 | J40: =J5+J6+J7+J8+J9+J10+J11+J12+J13+J14+J15+J16+J17+J18+J19+J20+J21+J22+J23+J24+J25+J26+J27+J28+J29+J30+J31+J32+J33+J34+J35+J36+J37+J38+J39 | K40: =K5+K6+K7+K8+K9+K10+K11+K12+K13+K14+K15+K16+K17+K18+K19+K20+K21+K22+K23+K24+K25+K26+K27+K28+K29+K30+K31+K32+K33+K34+K35+K36+K37+K38+K39 | L40: =L5+L6+L7+L8+L9+L10+L11+L12+L13+L14+L15+L16+L17+L18+L19+L20+L21+L22+L23+L24+L25+L26+L27+L28+L29+L30+L31+L32+L33+L34+L35+L36+L37+L38+L39 | M40: =M5+M6+M7+M8+M9+M10+M11+M12+M13+M14+M15+M16+M17+M18+M19+M20+M21+M22+M23+M24+M25+M26+M27+M28+M29+M30+M31+M32+M33+M34+M35+M36+M37+M38+M39 | N40: =N5+N6+N7+N8+N9+N10+N11+N12+N13+N14+N15+N16+N17+N18+N19+N20+N21+N22+N23+N24+N25+N26+N27+N28+N29+N30+N31+N32+N33+N34+N35+N36+N37+N38+N39 | O40: =O5+O6+O7+O8+O9+O10+O11+O12+O13+O14+O15+O16+O17+O18+O19+O20+O21+O22+O23+O24+O25+O26+O27+O28+O29+O30+O31+O32+O33+O34+O35+O36+O37+O38+O39 | P40: =P5+P6+P7+P8+P9+P10+P11+P12+P13+P14+P15+P16+P17+P18+P19+P20+P21+P22+P23+P24+P25+P26+P27+P28+P29+P30+P31+P32+P33+P34+P35+P36+P37+P38+P39 | Q40: =Q5+Q6+Q7+Q8+Q9+Q10+Q11+Q12+Q13+Q14+Q15+Q16+Q17+Q18+Q19+Q20+Q21+Q22+Q23+Q24+Q25+Q26+Q27+Q28+Q29+Q30+Q31+Q32+Q33+Q34+Q35+Q36+Q37+Q38+Q39 | ... AG40: =AG5+AG6+AG7+AG8+AG9+AG10+AG11+AG12+AG13+AG14+AG15+AG16+AG17+AG18+AG19+AG20+AG21+AG22+AG23+AG24+AG25+AG26+AG27+AG28+AG29+AG30+AG31+AG32+AG33+AG34+AG35+AG36+AG37+AG38+AG39 | AH40: =AH5+AH10+AH15+AH20+AH25+AH30+AH35 | AI40: =AI5+AI10+AI15+AI20+AI25+AI30+AI35 | AJ40: =AJ5+AJ10+AJ15+AJ20+AJ25+AJ30+AJ35 | AK40: =AK5+AK10+AK15+AK20+AK25+AK30+AK35 | AL40: =AL5+AL10+AL15+AL20+AL25+AL30+AL35 | AM40: =AM5+AM10+AM15+AM20+AM25+AM30+AM35 | AN40: =AN5+AN10+AN15+AN20+AN25+AN30+AN35

Sheet 13
A1: Лист для ежедневной регистрации грязного белья и постельных принадлежностей (в кг)
A2: Дата | B2: Вид стирки | C2: Количество | D2: Общее время | E2: EMULSIFIER | F2: ALKALINE | G2: BLEACH | H2: SOFTENER | I2: NEUTRLIZER | J2: Вес | AH2: Всего Вес | AI2: Ваниш | AK2: Ленор | AM2: Порошок
J3: 1 | L3: 2 | N3: 3 | P3: 4 | R3: 5 | T3: 6 | V3: 7 | X3: 8 | Z3: 9 | AB3: 10 | AD3: 11 | AF3: 12
J4: день | K4: ночь | L4: день | M4: ночь | N4: день | O4: ночь | P4: день | Q4: ночь | R4: день | S4: ночь | T4: день | U4: ночь | V4: день | W4: ночь | X4: день | Y4: ночь | Z4: день | AA4: ночь | AB4: день | AC4: ночь | AD4: день | AE4: ночь | AF4: день | AG4: ночь | AI4: Кол-во | AJ4: Общее | AK4: Кол-во | AL4: Общее | AM4: Кол-во | AN4: Общее
B5: Постель белая | C5: =COUNT(J5:AG9) | D5: =C5*57 | E5: =C5*55*3 | F5: =C5*55*8 | G5: =C5*55*6 | H5: =C5*55*4 | I5: =C5*55*1 | AH5: =SUM(J5:AG9) | AJ5: =AI5*5 | AL5: =AK5*50 | AN5: =AM5*175
B10: Махра белая | C10: =COUNT(J10:AG14) | D10: =C10*51 | E10: =C10*55*3 | F10: =C10*55*8 | G10: =C10*55*6 | H10: =C10*55*5 | I10: =C10*55*1 | AH10: =SUM(J10:AG14) | AJ10: =AI10*5 | AL10: =AK10*50 | AN10: =AM10*175
B15: Униформа белая | C15: =COUNT(J15:AG19) | D15: =C15*55 | E15: =C15*55*3 | F15: =C15*55*8 | G15: =C15*55*5 | H15: =C15*55*3 | I15: =C15*55*1 | AH15: =SUM(J15:AG19) | AJ15: =AI15*5 | AL15: =AK15*50 | AN15: =AM15*175
B20: Униформа темная | C20: =COUNT(J20:AG24) | D20: =C20*45 | E20: =C20*55*2 | F20: =C20*55*6 | G20: =C20*55*0 | H20: =C20*55*3 | I20: =C20*55*1 | AH20: =SUM(J20:AG24) | AJ20: =AI20*5 | AL20: =AK20*50 | AN20: =AM20*175
B25: Синтетика | C25: =COUNT(J25:AG29) | D25: =C25*38 | E25: =C25*55*3 | F25: =C25*55*5 | G25: =C25*55*0 | H25: =C25*55*3 | I25: =C25*55*1 | AH25: =SUM(J25:AG29) | AJ25: =AI25*5 | AL25: =AK25*50 | AN25: =AM25*175
B30: Деликатная | C30: =COUNT(J30:AG34) | D30: =C30*50 | E30: =C30*55*2 | F30: =C30*55*4 | G30: =C30*55*0 | H30: =C30*55*3 | I30: =C30*55*1 | AH30: =SUM(J30:AG34) | AJ30: =AI30*5 | AL30: =AK30*50 | AN30: =AM30*175
B35: Спецодежда | C35: =COUNT(J35:AG39) | D35: =C35*42 | E35: =C35*55*3 | F35: =C35*55*10 | G35: =C35*55*0 | H35: =C35*55*3 | I35: =C35*55*1 | AH35: =SUM(J35:AG39) | AJ35: =AI35*5 | AL35: =AK35*50 | AN35: =AM35*175
A40: ИТОГО | C40: =C5+C10+C15+C20+C25+C30+C35 | D40: =D5+D10+D15+D20+D25+D30+D35 | E40: =E5+E10+E15+E20+E25+E30+E35 | F40: =F5+F10+F15+F20+F25+F30+F35 | G40: =G5+G10+G15+G20+G25+G30+G35 | H40: =H5+H10+H15+H20+H25+H30+H35 | I40: =I5+I10+I15+I20+I25+I30+I35 | J40: =J5+J6+J7+J8+J9+J10+J11+J12+J13+J14+J15+J16+J17+J18+J19+J20+J21+J22+J23+J24+J25+J26+J27+J28+J29+J30+J31+J32+J33+J34+J35+J36+J37+J38+J39 | K40: =K5+K6+K7+K8+K9+K10+K11+K12+K13+K14+K15+K16+K17+K18+K19+K20+K21+K22+K23+K24+K25+K26+K27+K28+K29+K30+K31+K32+K33+K34+K35+K36+K37+K38+K39 | L40: =L5+L6+L7+L8+L9+L10+L11+L12+L13+L14+L15+L16+L17+L18+L19+L20+L21+L22+L23+L24+L25+L26+L27+L28+L29+L30+L31+L32+L33+L34+L35+L36+L37+L38+L39 | M40: =M5+M6+M7+M8+M9+M10+M11+M12+M13+M14+M15+M16+M17+M18+M19+M20+M21+M22+M23+M24+M25+M26+M27+M28+M29+M30+M31+M32+M33+M34+M35+M36+M37+M38+M39 | N40: =N5+N6+N7+N8+N9+N10+N11+N12+N13+N14+N15+N16+N17+N18+N19+N20+N21+N22+N23+N24+N25+N26+N27+N28+N29+N30+N31+N32+N33+N34+N35+N36+N37+N38+N39 | O40: =O5+O6+O7+O8+O9+O10+O11+O12+O13+O14+O15+O16+O17+O18+O19+O20+O21+O22+O23+O24+O25+O26+O27+O28+O29+O30+O31+O32+O33+O34+O35+O36+O37+O38+O39 | P40: =P5+P6+P7+P8+P9+P10+P11+P12+P13+P14+P15+P16+P17+P18+P19+P20+P21+P22+P23+P24+P25+P26+P27+P28+P29+P30+P31+P32+P33+P34+P35+P36+P37+P38+P39 | Q40: =Q5+Q6+Q7+Q8+Q9+Q10+Q11+Q12+Q13+Q14+Q15+Q16+Q17+Q18+Q19+Q20+Q21+Q22+Q23+Q24+Q25+Q26+Q27+Q28+Q29+Q30+Q31+Q32+Q33+Q34+Q35+Q36+Q37+Q38+Q39 | ... AG40: =AG5+AG6+AG7+AG8+AG9+AG10+AG11+AG12+AG13+AG14+AG15+AG16+AG17+AG18+AG19+AG20+AG21+AG22+AG23+AG24+AG25+AG26+AG27+AG28+AG29+AG30+AG31+AG32+AG33+AG34+AG35+AG36+AG37+AG38+AG39 | AH40: =AH5+AH10+AH15+AH20+AH25+AH30+AH35 | AI40: =AI5+AI10+AI15+AI20+AI25+AI30+AI35 | AJ40: =AJ5+AJ10+AJ15+AJ20+AJ25+AJ30+AJ35 | AK40: =AK5+AK10+AK15+AK20+AK25+AK30+AK35 | AL40: =AL5+AL10+AL15+AL20+AL25+AL30+AL35 | AM40: =AM5+AM10+AM15+AM20+AM25+AM30+AM35 | AN40: =AN5+AN10+AN15+AN20+AN25+AN30+AN35

Sheet 14
A1: Лист для ежедневной регистрации грязного белья и постельных принадлежностей (в кг)
A2: Дата | B2: Вид стирки | C2: Количество | D2: Общее время | E2: EMULSIFIER | F2: ALKALINE | G2: BLEACH | H2: SOFTENER | I2: NEUTRLIZER | J2: Вес | AH2: Всего Вес | AI2: Ваниш | AK2: Ленор | AM2: Порошок
J3: 1 | L3: 2 | N3: 3 | P3: 4 | R3: 5 | T3: 6 | V3: 7 | X3: 8 | Z3: 9 | AB3: 10 | AD3: 11 | AF3: 12
J4: день | K4: ночь | L4: день | M4: ночь | N4: день | O4: ночь | P4: день | Q4: ночь | R4: день | S4: ночь | T4: день | U4: ночь | V4: день | W4: ночь | X4: день | Y4: ночь | Z4: день | AA4: ночь | AB4: день | AC4: ночь | AD4: день | AE4: ночь | AF4: день | AG4: ночь | AI4: Кол-во | AJ4: Общее | AK4: Кол-во | AL4: Общее | AM4: Кол-во | AN4: Общее
B5: Постель белая | C5: =COUNT(J5:AG9) | D5: =C5*57 | E5: =C5*55*3 | F5: =C5*55*8 | G5: =C5*55*6 | H5: =C5*55*4 | I5: =C5*55*1 | AH5: =SUM(J5:AG9) | AJ5: =AI5*5 | AL5: =AK5*50 | AN5: =AM5*175
B10: Махра белая | C10: =COUNT(J10:AG14) | D10: =C10*51 | E10: =C10*55*3 | F10: =C10*55*8 | G10: =C10*55*6 | H10: =C10*55*5 | I10: =C10*55*1 | AH10: =SUM(J10:AG14) | AJ10: =AI10*5 | AL10: =AK10*50 | AN10: =AM10*175
B15: Униформа белая | C15: =COUNT(J15:AG19) | D15: =C15*55 | E15: =C15*55*3 | F15: =C15*55*8 | G15: =C15*55*5 | H15: =C15*55*3 | I15: =C15*55*1 | AH15: =SUM(J15:AG19) | AJ15: =AI15*5 | AL15: =AK15*50 | AN15: =AM15*175
B20: Униформа темная | C20: =COUNT(J20:AG24) | D20: =C20*45 | E20: =C20*55*2 | F20: =C20*55*6 | G20: =C20*55*0 | H20: =C20*55*3 | I20: =C20*55*1 | AH20: =SUM(J20:AG24) | AJ20: =AI20*5 | AL20: =AK20*50 | AN20: =AM20*175
B25: Синтетика | C25: =COUNT(J25:AG29) | D25: =C25*38 | E25: =C25*55*3 | F25: =C25*55*5 | G25: =C25*55*0 | H25: =C25*55*3 | I25: =C25*55*1 | AH25: =SUM(J25:AG29) | AJ25: =AI25*5 | AL25: =AK25*50 | AN25: =AM25*175
B30: Деликатная | C30: =COUNT(J30:AG34) | D30: =C30*50 | E30: =C30*55*2 | F30: =C30*55*4 | G30: =C30*55*0 | H30: =C30*55*3 | I30: =C30*55*1 | AH30: =SUM(J30:AG34) | AJ30: =AI30*5 | AL30: =AK30*50 | AN30: =AM30*175
B35: Спецодежда | C35: =COUNT(J35:AG39) | D35: =C35*42 | E35: =C35*55*3 | F35: =C35*55*10 | G35: =C35*55*0 | H35: =C35*55*3 | I35: =C35*55*1 | AH35: =SUM(J35:AG39) | AJ35: =AI35*5 | AL35: =AK35*50 | AN35: =AM35*175
A40: ИТОГО | C40: =C5+C10+C15+C20+C25+C30+C35 | D40: =D5+D10+D15+D20+D25+D30+D35 | E40: =E5+E10+E15+E20+E25+E30+E35 | F40: =F5+F10+F15+F20+F25+F30+F35 | G40: =G5+G10+G15+G20+G25+G30+G35 | H40: =H5+H10+H15+H20+H25+H30+H35 | I40: =I5+I10+I15+I20+I25+I30+I35 | J40: =J5+J6+J7+J8+J9+J10+J11+J12+J13+J14+J15+J16+J17+J18+J19+J20+J21+J22+J23+J24+J25+J26+J27+J28+J29+J30+J31+J32+J33+J34+J35+J36+J37+J38+J39 | K40: =K5+K6+K7+K8+K9+K10+K11+K12+K13+K14+K15+K16+K17+K18+K19+K20+K21+K22+K23+K24+K25+K26+K27+K28+K29+K30+K31+K32+K33+K34+K35+K36+K37+K38+K39 | L40: =L5+L6+L7+L8+L9+L10+L11+L12+L13+L14+L15+L16+L17+L18+L19+L20+L21+L22+L23+L24+L25+L26+L27+L28+L29+L30+L31+L32+L33+L34+L35+L36+L37+L38+L39 | M40: =M5+M6+M7+M8+M9+M10+M11+M12+M13+M14+M15+M16+M17+M18+M19+M20+M21+M22+M23+M24+M25+M26+M27+M28+M29+M30+M31+M32+M33+M34+M35+M36+M37+M38+M39 | N40: =N5+N6+N7+N8+N9+N10+N11+N12+N13+N14+N15+N16+N17+N18+N19+N20+N21+N22+N23+N24+N25+N26+N27+N28+N29+N30+N31+N32+N33+N34+N35+N36+N37+N38+N39 | O40: =O5+O6+O7+O8+O9+O10+O11+O12+O13+O14+O15+O16+O17+O18+O19+O20+O21+O22+O23+O24+O25+O26+O27+O28+O29+O30+O31+O32+O33+O34+O35+O36+O37+O38+O39 | P40: =P5+P6+P7+P8+P9+P10+P11+P12+P13+P14+P15+P16+P17+P18+P19+P20+P21+P22+P23+P24+P25+P26+P27+P28+P29+P30+P31+P32+P33+P34+P35+P36+P37+P38+P39 | Q40: =Q5+Q6+Q7+Q8+Q9+Q10+Q11+Q12+Q13+Q14+Q15+Q16+Q17+Q18+Q19+Q20+Q21+Q22+Q23+Q24+Q25+Q26+Q27+Q28+Q29+Q30+Q31+Q32+Q33+Q34+Q35+Q36+Q37+Q38+Q39 | ... AG40: =AG5+AG6+AG7+AG8+AG9+AG10+AG11+AG12+AG13+AG14+AG15+AG16+AG17+AG18+AG19+AG20+AG21+AG22+AG23+AG24+AG25+AG26+AG27+AG28+AG29+AG30+AG31+AG32+AG33+AG34+AG35+AG36+AG37+AG38+AG39 | AH40: =AH5+AH10+AH15+AH20+AH25+AH30+AH35 | AI40: =AI5+AI10+AI15+AI20+AI25+AI30+AI35 | AJ40: =AJ5+AJ10+AJ15+AJ20+AJ25+AJ30+AJ35 | AK40: =AK5+AK10+AK15+AK20+AK25+AK30+AK35 | AL40: =AL5+AL10+AL15+AL20+AL25+AL30+AL35 | AM40: =AM5+AM10+AM15+AM20+AM25+AM30+AM35 | AN40: =AN5+AN10+AN15+AN20+AN25+AN30+AN35

Sheet 15
A1: Лист для ежедневной регистрации грязного белья и постельных принадлежностей (в кг)
A2: Дата | B2: Вид стирки | C2: Количество | D2: Общее время | E2: EMULSIFIER | F2: ALKALINE | G2: BLEACH | H2: SOFTENER | I2: NEUTRLIZER | J2: Вес | AH2: Всего Вес | AI2: Ваниш | AK2: Ленор | AM2: Порошок
J3: 1 | L3: 2 | N3: 3 | P3: 4 | R3: 5 | T3: 6 | V3: 7 | X3: 8 | Z3: 9 | AB3: 10 | AD3: 11 | AF3: 12
J4: день | K4: ночь | L4: день | M4: ночь | N4: день | O4: ночь | P4: день | Q4: ночь | R4: день | S4: ночь | T4: день | U4: ночь | V4: день | W4: ночь | X4: день | Y4: ночь | Z4: день | AA4: ночь | AB4: день | AC4: ночь | AD4: день | AE4: ночь | AF4: день | AG4: ночь | AI4: Кол-во | AJ4: Общее | AK4: Кол-во | AL4: Общее | AM4: Кол-во | AN4: Общее
B5: Постель белая | C5: =COUNT(J5:AG9) | D5: =C5*57 | E5: =C5*55*3 | F5: =C5*55*8 | G5: =C5*55*6 | H5: =C5*55*4 | I5: =C5*55*1 | AH5: =SUM(J5:AG9) | AJ5: =AI5*5 | AL5: =AK5*50 | AN5: =AM5*175
B10: Махра белая | C10: =COUNT(J10:AG14) | D10: =C10*51 | E10: =C10*55*3 | F10: =C10*55*8 | G10: =C10*55*6 | H10: =C10*55*5 | I10: =C10*55*1 | AH10: =SUM(J10:AG14) | AJ10: =AI10*5 | AL10: =AK10*50 | AN10: =AM10*175
B15: Униформа белая | C15: =COUNT(J15:AG19) | D15: =C15*55 | E15: =C15*55*3 | F15: =C15*55*8 | G15: =C15*55*5 | H15: =C15*55*3 | I15: =C15*55*1 | AH15: =SUM(J15:AG19) | AJ15: =AI15*5 | AL15: =AK15*50 | AN15: =AM15*175
B20: Униформа темная | C20: =COUNT(J20:AG24) | D20: =C20*45 | E20: =C20*55*2 | F20: =C20*55*6 | G20: =C20*55*0 | H20: =C20*55*3 | I20: =C20*55*1 | AH20: =SUM(J20:AG24) | AJ20: =AI20*5 | AL20: =AK20*50 | AN20: =AM20*175
B25: Синтетика | C25: =COUNT(J25:AG29) | D25: =C25*38 | E25: =C25*55*3 | F25: =C25*55*5 | G25: =C25*55*0 | H25: =C25*55*3 | I25: =C25*55*1 | AH25: =SUM(J25:AG29) | AJ25: =AI25*5 | AL25: =AK25*50 | AN25: =AM25*175
B30: Деликатная | C30: =COUNT(J30:AG34) | D30: =C30*50 | E30: =C30*55*2 | F30: =C30*55*4 | G30: =C30*55*0 | H30: =C30*55*3 | I30: =C30*55*1 | AH30: =SUM(J30:AG34) | AJ30: =AI30*5 | AL30: =AK30*50 | AN30: =AM30*175
B35: Спецодежда | C35: =COUNT(J35:AG39) | D35: =C35*42 | E35: =C35*55*3 | F35: =C35*55*10 | G35: =C35*55*0 | H35: =C35*55*3 | I35: =C35*55*1 | AH35: =SUM(J35:AG39) | AJ35: =AI35*5 | AL35: =AK35*50 | AN35: =AM35*175
